Workbook

Sheet maze_foe_v8
A1: paipaiworld_config
A2: INT_K | B2: STRING | C2: STRING | D2: STRING | E2: STRING | F2: STRING | G2: INT_C_S | H2: INT_C_S | I2: MAP<INT:LONG>_C_S | J2: LIST<INT>_C_S | K2: STRING_C_S | L2: INT_C_S | M2: INT_C_S | N2: INT_C_S | O2: INT_C_S | P2: INT_C_S | Q2: INT_C_S | R2: INT_C_S | S2: INT_C_S | T2: INT_C_S | U2: INT_C_S | V2: MAP<INT:LONG>_C_S | W2: MAP<INT:LONG>_C_S | X2: MAP<INT:LONG>_C_S | Y2: INT_C_S | Z2: LIST<INT>_C_S | AA2: INT_S_C | AB2: MAP<LONG:INT>_S | AC2: INT_C_S | AD2: INT_C_S | AE2: INT_C_S | AF2: INT_C_S | AG2: INT_C_S | AH2: INT_C_S | AI2: INT_C_S | AJ2: INT_C_S
A3: order | B3: desc0 | C3: desc1 | D3: desc2 | E3: desc3 | F3: desc4 | G3: in_barries_id | H3: foe_type | I3: drop_item | J3: drop_equip | K3: name | L3: model_id | M3: level | N3: kongfu | O3: hp_lose_type | P3: attack_max | Q3: def_max | R3: hp_max | S3: speed | T3: hp_num | U3: tough_max | V3: drop_exp_num | W3: drop_coin_num | X3: drop_equip_score_num | Y3: nor_attack_skill_id | Z3: passive_skill_id | AA3: drop_energy_num | AB3: tough_borke_raitio | AC3: attack_speed_pro | AD3: be_attack_recovery_speed_pro | AE3: tough_deplete | AF3: search_for_scope | AG3: attacked_back_range | AH3: attacked_back_range_after | AI3: threat_value | AJ3: arrow_threat_value
A4: 怪物id | B4: 关卡数 | C4: 怪物类型 | D4: 怪物类型 | E4: 模型名称索引 | F4: 是否有模型 | G4: 所属关卡id | H4: 怪物类型（1-小怪 2-守关boss 3-巡逻守卫 | I4: 怪物掉落物品 | J4: 怪物掉落装备 | K4: 怪物名称 | L4: 资源组id | M4: 怪物等级 | N4: 怪物武力值 | O4: 损血类型 | P4: 怪物攻击 | Q4: 怪物防御 | R4: 怪物血量 | S4: 移动速度(万分比） | T4: 血条数量 | U4: 怪物韧性上限 | V4: 冒险等级:掉落经验数量 | W4: 冒险等级:掉落钱币数量 | X4: 冒险等级:掉落装备分数量 | Y4: 普通攻击技能id | Z4: 被动技能id | AA4: 死亡后掉落的能量点数 | AB4: 武力对应削韧倍率（万分比） | AC4: 怪物攻击速度系数（>10000加速 ,<10000减速 | AD4: 受击回复动作播放速度系数（>10000加速 ,<10000减速 | AE4: 韧性被打空时释放技能 | AF4: 寻敌范围调整值（默认10米） | AG4: 被击退距离系数（万分比） | AH4: 被击退距离系数（破除韧性后）（万分比） | AI4: 威胁值 | AJ4: 远程威胁值
A5: 10201 | B5: 1 | C5: 守卫1 | D5: 雷霆魔头3 | E5: 未使用 | F5: 客户端资源组 | G5: 1 | H5: 2 | I5: 0:0 | J5: 0 | K5: 800001021 | L5: 800001021 | M5: 1 | N5: 1 | O5: 1 | P5: 8 | Q5: 0 | R5: 25 | S5: -3000 | T5: 1 | U5: 0 | V5: 1:0_2:0_3:0_4:0_5:0_6:0_7:0_8:0_9:0_10:0_11:0_12:0_13:0_14:0_15:0_16:0_17:0_18:0_19:0_20:0_21:0_22:0_23:0_24:0_25:0_26:0_27:0_28:0_29:0_30:0_31:0_32:0_33:0_34:0_35:0_36:0_37:0_38:0_39:0_40:0_41:0_42:0_43:0_44:0_45:0_46:0_47:0_48:0_49:0_50:0_51:0_52:0_53:0_54:0_55:0_56:0_57:0_58:0_59:0_60:0_61:0_62:0_63:0_64:0_65:0_66:0_67:0_68:0_69:0_70:0_71:0_72:0_73:0_74:0_75:0_76:0_77:0_78:0_79:0_80:0_81:0_82:0_83:0_84:0_85:0_86:0_87:0_88:0_89:0_90:0_91:0_92:0_93:0_94:0_95:0_96:0_97:0_98:0_99:0_100:0_101:0_102:0_103:0_104:0_105:0_106:0_107:0_108:0_109:0_110:0_111:0_112:0_113:0_114:0_115:0_116:0_117:0_118:0_119:0_120:0_121:0_122:0_123:0_124:0_125:0_126:0_127:0_128:0_129:0_130:0_131:0_132:0_133:0_134:0_135:0_136:0_137:0_138:0_139:0_140:0_141:0_142:0_143:0_144:0_145:0_146:0_147:0_148:0_149:0_150:0_151:0_152:0_153:0_154:0_155:0_156:0_157:0_158:0_159:0_160:0 | W5: 1:0_2:0_3:0_4:0_5:0_6:0_7:0_8:0_9:0_10:0_11:0_12:0_13:0_14:0_15:0_16:0_17:0_18:0_19:0_20:0_21:0_22:0_23:0_24:0_25:0_26:0_27:0_28:0_29:0_30:0_31:0_32:0_33:0_34:0_35:0_36:0_37:0_38:0_39:0_40:0_41:0_42:0_43:0_44:0_45:0_46:0_47:0_48:0_49:0_50:0_51:0_52:0_53:0_54:0_55:0_56:0_57:0_58:0_59:0_60:0_61:0_62:0_63:0_64:0_65:0_66:0_67:0_68:0_69:0_70:0_71:0_72:0_73:0_74:0_75:0_76:0_77:0_78:0_79:0_80:0_81:0_82:0_83:0_84:0_85:0_86:0_87:0_88:0_89:0_90:0_91:0_92:0_93:0_94:0_95:0_96:0_97:0_98:0_99:0_100:0_101:0_102:0_103:0_104:0_105:0_106:0_107:0_108:0_109:0_110:0_111:0_112:0_113:0_114:0_115:0_116:0_117:0_118:0_119:0_120:0_121:0_122:0_123:0_124:0_125:0_126:0_127:0_128:0_129:0_130:0_131:0_132:0_133:0_134:0_135:0_136:0_137:0_138:0_139:0_140:0_141:0_142:0_143:0_144:0_145:0_146:0_147:0_148:0_149:0_150:0_151:0_152:0_153:0_154:0_155:0_156:0_157:0_158:0_159:0_160:0 | X5: 1:0_2:0_3:0_4:0_5:0_6:0_7:0_8:0_9:0_10:0_11:0_12:0_13:0_14:0_15:0_16:0_17:0_18:0_19:0_20:0_21:0_22:0_23:0_24:0_25:0_26:0_27:0_28:0_29:0_30:0_31:0_32:0_33:0_34:0_35:0_36:0_37:0_38:0_39:0_40:0_41:0_42:0_43:0_44:0_45:0_46:0_47:0_48:0_49:0_50:0_51:0_52:0_53:0_54:0_55:0_56:0_57:0_58:0_59:0_60:0_61:0_62:0_63:0_64:0_65:0_66:0_67:0_68:0_69:0_70:0_71:0_72:0_73:0_74:0_75:0_76:0_77:0_78:0_79:0_80:0_81:0_82:0_83:0_84:0_85:0_86:0_87:0_88:0_89:0_90:0_91:0_92:0_93:0_94:0_95:0_96:0_97:0_98:0_99:0_100:0_101:0_102:0_103:0_104:0_105:0_106:0_107:0_108:0_109:0_110:0_111:0_112:0_113:0_114:0_115:0_116:0_117:0_118:0_119:0_120:0_121:0_122:0_123:0_124:0_125:0_126:0_127:0_128:0_129:0_130:0_131:0_132:0_133:0_134:0_135:0_136:0_137:0_138:0_139:0_140:0_141:0_142:0_143:0_144:0_145:0_146:0_147:0_148:0_149:0_150:0_151:0_152:0_153:0_154:0_155:0_156:0_157:0_158:0_159:0_160:0 | Y5: 20010001 | Z5: 0 | AA5: 1 | AB5: 0:2500_50:5000_80:10000_125:15000_160:30000 | AC5: 10000 | AD5: 10000 | AE5: 0 | AF5: 40 | AG5: 0 | AH5: 0 | AI5: 0 | AJ5: 0
A6: 10301 | B6: 1 | C6: 守卫2 | D6: 野猪怪 | E6: 未使用 | F6: 客户端资源组 | G6: 1 | H6: 2 | I6: 0:0 | J6: 0 | K6: 800001021 | L6: 800001021 | M6: 1 | N6: 2 | O6: 2 | P6: 8 | Q6: 0 | R6: 25 | S6: -3000 | T6: 1 | U6: 0 | V6: 1:0_2:0_3:0_4:0_5:0_6:0_7:0_8:0_9:0_10:0_11:0_12:0_13:0_14:0_15:0_16:0_17:0_18:0_19:0_20:0_21:0_22:0_23:0_24:0_25:0_26:0_27:0_28:0_29:0_30:0_31:0_32:0_33:0_34:0_35:0_36:0_37:0_38:0_39:0_40:0_41:0_42:0_43:0_44:0_45:0_46:0_47:0_48:0_49:0_50:0_51:0_52:0_53:0_54:0_55:0_56:0_57:0_58:0_59:0_60:0_61:0_62:0_63:0_64:0_65:0_66:0_67:0_68:0_69:0_70:0_71:0_72:0_73:0_74:0_75:0_76:0_77:0_78:0_79:0_80:0_81:0_82:0_83:0_84:0_85:0_86:0_87:0_88:0_89:0_90:0_91:0_92:0_93:0_94:0_95:0_96:0_97:0_98:0_99:0_100:0_101:0_102:0_103:0_104:0_105:0_106:0_107:0_108:0_109:0_110:0_111:0_112:0_113:0_114:0_115:0_116:0_117:0_118:0_119:0_120:0_121:0_122:0_123:0_124:0_125:0_126:0_127:0_128:0_129:0_130:0_131:0_132:0_133:0_134:0_135:0_136:0_137:0_138:0_139:0_140:0_141:0_142:0_143:0_144:0_145:0_146:0_147:0_148:0_149:0_150:0_151:0_152:0_153:0_154:0_155:0_156:0_157:0_158:0_159:0_160:0 | W6: 1:0_2:0_3:0_4:0_5:0_6:0_7:0_8:0_9:0_10:0_11:0_12:0_13:0_14:0_15:0_16:0_17:0_18:0_19:0_20:0_21:0_22:0_23:0_24:0_25:0_26:0_27:0_28:0_29:0_30:0_31:0_32:0_33:0_34:0_35:0_36:0_37:0_38:0_39:0_40:0_41:0_42:0_43:0_44:0_45:0_46:0_47:0_48:0_49:0_50:0_51:0_52:0_53:0_54:0_55:0_56:0_57:0_58:0_59:0_60:0_61:0_62:0_63:0_64:0_65:0_66:0_67:0_68:0_69:0_70:0_71:0_72:0_73:0_74:0_75:0_76:0_77:0_78:0_79:0_80:0_81:0_82:0_83:0_84:0_85:0_86:0_87:0_88:0_89:0_90:0_91:0_92:0_93:0_94:0_95:0_96:0_97:0_98:0_99:0_100:0_101:0_102:0_103:0_104:0_105:0_106:0_107:0_108:0_109:0_110:0_111:0_112:0_113:0_114:0_115:0_116:0_117:0_118:0_119:0_120:0_121:0_122:0_123:0_124:0_125:0_126:0_127:0_128:0_129:0_130:0_131:0_132:0_133:0_134:0_135:0_136:0_137:0_138:0_139:0_140:0_141:0_142:0_143:0_144:0_145:0_146:0_147:0_148:0_149:0_150:0_151:0_152:0_153:0_154:0_155:0_156:0_157:0_158:0_159:0_160:0 | X6: 1:0_2:0_3:0_4:0_5:0_6:0_7:0_8:0_9:0_10:0_11:0_12:0_13:0_14:0_15:0_16:0_17:0_18:0_19:0_20:0_21:0_22:0_23:0_24:0_25:0_26:0_27:0_28:0_29:0_30:0_31:0_32:0_33:0_34:0_35:0_36:0_37:0_38:0_39:0_40:0_41:0_42:0_43:0_44:0_45:0_46:0_47:0_48:0_49:0_50:0_51:0_52:0_53:0_54:0_55:0_56:0_57:0_58:0_59:0_60:0_61:0_62:0_63:0_64:0_65:0_66:0_67:0_68:0_69:0_70:0_71:0_72:0_73:0_74:0_75:0_76:0_77:0_78:0_79:0_80:0_81:0_82:0_83:0_84:0_85:0_86:0_87:0_88:0_89:0_90:0_91:0_92:0_93:0_94:0_95:0_96:0_97:0_98:0_99:0_100:0_101:0_102:0_103:0_104:0_105:0_106:0_107:0_108:0_109:0_110:0_111:0_112:0_113:0_114:0_115:0_116:0_117:0_118:0_119:0_120:0_121:0_122:0_123:0_124:0_125:0_126:0_127:0_128:0_129:0_130:0_131:0_132:0_133:0_134:0_135:0_136:0_137:0_138:0_139:0_140:0_141:0_142:0_143:0_144:0_145:0_146:0_147:0_148:0_149:0_150:0_151:0_152:0_153:0_154:0_155:0_156:0_157:0_158:0_159:0_160:0 | Y6: 20010001 | Z6: 0 | AA6: 1 | AB6: 0:2500_50:5000_80:10000_125:15000_160:30000 | AC6: 10000 | AD6: 10000 | AE6: 0 | AF6: 40 | AG6: 0 | AH6: 0 | AI6: 0 | AJ6: 0
A7: 10302 | B7: 1 | C7: 守卫3 | D7: 喷火恶龙2 | E7: 未使用 | F7: 客户端资源组 | G7: 1 | H7: 2 | I7: 0:0 | J7: 0 | K7: 800001021 | L7: 800001021 | M7: 1 | N7: 3 | O7: 2 | P7: 8 | Q7: 0 | R7: 25 | S7: -3000 | T7: 1 | U7: 0 | V7: 1:0_2:0_3:0_4:0_5:0_6:0_7:0_8:0_9:0_10:0_11:0_12:0_13:0_14:0_15:0_16:0_17:0_18:0_19:0_20:0_21:0_22:0_23:0_24:0_25:0_26:0_27:0_28:0_29:0_30:0_31:0_32:0_33:0_34:0_35:0_36:0_37:0_38:0_39:0_40:0_41:0_42:0_43:0_44:0_45:0_46:0_47:0_48:0_49:0_50:0_51:0_52:0_53:0_54:0_55:0_56:0_57:0_58:0_59:0_60:0_61:0_62:0_63:0_64:0_65:0_66:0_67:0_68:0_69:0_70:0_71:0_72:0_73:0_74:0_75:0_76:0_77:0_78:0_79:0_80:0_81:0_82:0_83:0_84:0_85:0_86:0_87:0_88:0_89:0_90:0_91:0_92:0_93:0_94:0_95:0_96:0_97:0_98:0_99:0_100:0_101:0_102:0_103:0_104:0_105:0_106:0_107:0_108:0_109:0_110:0_111:0_112:0_113:0_114:0_115:0_116:0_117:0_118:0_119:0_120:0_121:0_122:0_123:0_124:0_125:0_126:0_127:0_128:0_129:0_130:0_131:0_132:0_133:0_134:0_135:0_136:0_137:0_138:0_139:0_140:0_141:0_142:0_143:0_144:0_145:0_146:0_147:0_148:0_149:0_150:0_151:0_152:0_153:0_154:0_155:0_156:0_157:0_158:0_159:0_160:0 | W7: 1:0_2:0_3:0_4:0_5:0_6:0_7:0_8:0_9:0_10:0_11:0_12:0_13:0_14:0_15:0_16:0_17:0_18:0_19:0_20:0_21:0_22:0_23:0_24:0_25:0_26:0_27:0_28:0_29:0_30:0_31:0_32:0_33:0_34:0_35:0_36:0_37:0_38:0_39:0_40:0_41:0_42:0_43:0_44:0_45:0_46:0_47:0_48:0_49:0_50:0_51:0_52:0_53:0_54:0_55:0_56:0_57:0_58:0_59:0_60:0_61:0_62:0_63:0_64:0_65:0_66:0_67:0_68:0_69:0_70:0_71:0_72:0_73:0_74:0_75:0_76:0_77:0_78:0_79:0_80:0_81:0_82:0_83:0_84:0_85:0_86:0_87:0_88:0_89:0_90:0_91:0_92:0_93:0_94:0_95:0_96:0_97:0_98:0_99:0_100:0_101:0_102:0_103:0_104:0_105:0_106:0_107:0_108:0_109:0_110:0_111:0_112:0_113:0_114:0_115:0_116:0_117:0_118:0_119:0_120:0_121:0_122:0_123:0_124:0_125:0_126:0_127:0_128:0_129:0_130:0_131:0_132:0_133:0_134:0_135:0_136:0_137:0_138:0_139:0_140:0_141:0_142:0_143:0_144:0_145:0_146:0_147:0_148:0_149:0_150:0_151:0_152:0_153:0_154:0_155:0_156:0_157:0_158:0_159:0_160:0 | X7: 1:0_2:0_3:0_4:0_5:0_6:0_7:0_8:0_9:0_10:0_11:0_12:0_13:0_14:0_15:0_16:0_17:0_18:0_19:0_20:0_21:0_22:0_23:0_24:0_25:0_26:0_27:0_28:0_29:0_30:0_31:0_32:0_33:0_34:0_35:0_36:0_37:0_38:0_39:0_40:0_41:0_42:0_43:0_44:0_45:0_46:0_47:0_48:0_49:0_50:0_51:0_52:0_53:0_54:0_55:0_56:0_57:0_58:0_59:0_60:0_61:0_62:0_63:0_64:0_65:0_66:0_67:0_68:0_69:0_70:0_71:0_72:0_73:0_74:0_75:0_76:0_77:0_78:0_79:0_80:0_81:0_82:0_83:0_84:0_85:0_86:0_87:0_88:0_89:0_90:0_91:0_92:0_93:0_94:0_95:0_96:0_97:0_98:0_99:0_100:0_101:0_102:0_103:0_104:0_105:0_106:0_107:0_108:0_109:0_110:0_111:0_112:0_113:0_114:0_115:0_116:0_117:0_118:0_119:0_120:0_121:0_122:0_123:0_124:0_125:0_126:0_127:0_128:0_129:0_130:0_131:0_132:0_133:0_134:0_135:0_136:0_137:0_138:0_139:0_140:0_141:0_142:0_143:0_144:0_145:0_146:0_147:0_148:0_149:0_150:0_151:0_152:0_153:0_154:0_155:0_156:0_157:0_158:0_159:0_160:0 | Y7: 20010001 | Z7: 0 | AA7: 1 | AB7: 0:2500_50:5000_80:10000_125:15000_160:30000 | AC7: 10000 | AD7: 10000 | AE7: 0 | AF7: 40 | AG7: 0 | AH7: 0 | AI7: 0 | AJ7: 0
A8: 10303 | B8: 1 | C8: 守卫4 | D8: 爆裂悍匪2 | E8: 未使用 | F8: 客户端资源组 | G8: 1 | H8: 2 | I8: 0:0 | J8: 0 | K8: 800001021 | L8: 800001021 | M8: 1 | N8: 4 | O8: 2 | P8: 8 | Q8: 0 | R8: 25 | S8: -3000 | T8: 1 | U8: 0 | V8: 1:0_2:0_3:0_4:0_5:0_6:0_7:0_8:0_9:0_10:0_11:0_12:0_13:0_14:0_15:0_16:0_17:0_18:0_19:0_20:0_21:0_22:0_23:0_24:0_25:0_26:0_27:0_28:0_29:0_30:0_31:0_32:0_33:0_34:0_35:0_36:0_37:0_38:0_39:0_40:0_41:0_42:0_43:0_44:0_45:0_46:0_47:0_48:0_49:0_50:0_51:0_52:0_53:0_54:0_55:0_56:0_57:0_58:0_59:0_60:0_61:0_62:0_63:0_64:0_65:0_66:0_67:0_68:0_69:0_70:0_71:0_72:0_73:0_74:0_75:0_76:0_77:0_78:0_79:0_80:0_81:0_82:0_83:0_84:0_85:0_86:0_87:0_88:0_89:0_90:0_91:0_92:0_93:0_94:0_95:0_96:0_97:0_98:0_99:0_100:0_101:0_102:0_103:0_104:0_105:0_106:0_107:0_108:0_109:0_110:0_111:0_112:0_113:0_114:0_115:0_116:0_117:0_118:0_119:0_120:0_121:0_122:0_123:0_124:0_125:0_126:0_127:0_128:0_129:0_130:0_131:0_132:0_133:0_134:0_135:0_136:0_137:0_138:0_139:0_140:0_141:0_142:0_143:0_144:0_145:0_146:0_147:0_148:0_149:0_150:0_151:0_152:0_153:0_154:0_155:0_156:0_157:0_158:0_159:0_160:0 | W8: 1:0_2:0_3:0_4:0_5:0_6:0_7:0_8:0_9:0_10:0_11:0_12:0_13:0_14:0_15:0_16:0_17:0_18:0_19:0_20:0_21:0_22:0_23:0_24:0_25:0_26:0_27:0_28:0_29:0_30:0_31:0_32:0_33:0_34:0_35:0_36:0_37:0_38:0_39:0_40:0_41:0_42:0_43:0_44:0_45:0_46:0_47:0_48:0_49:0_50:0_51:0_52:0_53:0_54:0_55:0_56:0_57:0_58:0_59:0_60:0_61:0_62:0_63:0_64:0_65:0_66:0_67:0_68:0_69:0_70:0_71:0_72:0_73:0_74:0_75:0_76:0_77:0_78:0_79:0_80:0_81:0_82:0_83:0_84:0_85:0_86:0_87:0_88:0_89:0_90:0_91:0_92:0_93:0_94:0_95:0_96:0_97:0_98:0_99:0_100:0_101:0_102:0_103:0_104:0_105:0_106:0_107:0_108:0_109:0_110:0_111:0_112:0_113:0_114:0_115:0_116:0_117:0_118:0_119:0_120:0_121:0_122:0_123:0_124:0_125:0_126:0_127:0_128:0_129:0_130:0_131:0_132:0_133:0_134:0_135:0_136:0_137:0_138:0_139:0_140:0_141:0_142:0_143:0_144:0_145:0_146:0_147:0_148:0_149:0_150:0_151:0_152:0_153:0_154:0_155:0_156:0_157:0_158:0_159:0_160:0 | X8: 1:0_2:0_3:0_4:0_5:0_6:0_7:0_8:0_9:0_10:0_11:0_12:0_13:0_14:0_15:0_16:0_17:0_18:0_19:0_20:0_21:0_22:0_23:0_24:0_25:0_26:0_27:0_28:0_29:0_30:0_31:0_32:0_33:0_34:0_35:0_36:0_37:0_38:0_39:0_40:0_41:0_42:0_43:0_44:0_45:0_46:0_47:0_48:0_49:0_50:0_51:0_52:0_53:0_54:0_55:0_56:0_57:0_58:0_59:0_60:0_61:0_62:0_63:0_64:0_65:0_66:0_67:0_68:0_69:0_70:0_71:0_72:0_73:0_74:0_75:0_76:0_77:0_78:0_79:0_80:0_81:0_82:0_83:0_84:0_85:0_86:0_87:0_88:0_89:0_90:0_91:0_92:0_93:0_94:0_95:0_96:0_97:0_98:0_99:0_100:0_101:0_102:0_103:0_104:0_105:0_106:0_107:0_108:0_109:0_110:0_111:0_112:0_113:0_114:0_115:0_116:0_117:0_118:0_119:0_120:0_121:0_122:0_123:0_124:0_125:0_126:0_127:0_128:0_129:0_130:0_131:0_132:0_133:0_134:0_135:0_136:0_137:0_138:0_139:0_140:0_141:0_142:0_143:0_144:0_145:0_146:0_147:0_148:0_149:0_150:0_151:0_152:0_153:0_154:0_155:0_156:0_157:0_158:0_159:0_160:0 | Y8: 20010001 | Z8: 0 | AA8: 1 | AB8: 0:2500_50:5000_80:10000_125:15000_160:30000 | AC8: 10000 | AD8: 10000 | AE8: 0 | AF8: 40 | AG8: 0 | AH8: 0 | AI8: 0 | AJ8: 0
A9: 10304 | B9: 1 | C9: 守卫5 | D9: 斯巴达勇士2 | E9: 未使用 | F9: 客户端资源组 | G9: 1 | H9: 2 | I9: 0:0 | J9: 0 | K9: 800001021 | L9: 800001021 | M9: 1 | N9: 4 | O9: 2 | P9: 8 | Q9: 0 | R9: 25 | S9: -3000 | T9: 1 | U9: 0 | V9: 1:0_2:0_3:0_4:0_5:0_6:0_7:0_8:0_9:0_10:0_11:0_12:0_13:0_14:0_15:0_16:0_17:0_18:0_19:0_20:0_21:0_22:0_23:0_24:0_25:0_26:0_27:0_28:0_29:0_30:0_31:0_32:0_33:0_34:0_35:0_36:0_37:0_38:0_39:0_40:0_41:0_42:0_43:0_44:0_45:0_46:0_47:0_48:0_49:0_50:0_51:0_52:0_53:0_54:0_55:0_56:0_57:0_58:0_59:0_60:0_61:0_62:0_63:0_64:0_65:0_66:0_67:0_68:0_69:0_70:0_71:0_72:0_73:0_74:0_75:0_76:0_77:0_78:0_79:0_80:0_81:0_82:0_83:0_84:0_85:0_86:0_87:0_88:0_89:0_90:0_91:0_92:0_93:0_94:0_95:0_96:0_97:0_98:0_99:0_100:0_101:0_102:0_103:0_104:0_105:0_106:0_107:0_108:0_109:0_110:0_111:0_112:0_113:0_114:0_115:0_116:0_117:0_118:0_119:0_120:0_121:0_122:0_123:0_124:0_125:0_126:0_127:0_128:0_129:0_130:0_131:0_132:0_133:0_134:0_135:0_136:0_137:0_138:0_139:0_140:0_141:0_142:0_143:0_144:0_145:0_146:0_147:0_148:0_149:0_150:0_151:0_152:0_153:0_154:0_155:0_156:0_157:0_158:0_159:0_160:0 | W9: 1:0_2:0_3:0_4:0_5:0_6:0_7:0_8:0_9:0_10:0_11:0_12:0_13:0_14:0_15:0_16:0_17:0_18:0_19:0_20:0_21:0_22:0_23:0_24:0_25:0_26:0_27:0_28:0_29:0_30:0_31:0_32:0_33:0_34:0_35:0_36:0_37:0_38:0_39:0_40:0_41:0_42:0_43:0_44:0_45:0_46:0_47:0_48:0_49:0_50:0_51:0_52:0_53:0_54:0_55:0_56:0_57:0_58:0_59:0_60:0_61:0_62:0_63:0_64:0_65:0_66:0_67:0_68:0_69:0_70:0_71:0_72:0_73:0_74:0_75:0_76:0_77:0_78:0_79:0_80:0_81:0_82:0_83:0_84:0_85:0_86:0_87:0_88:0_89:0_90:0_91:0_92:0_93:0_94:0_95:0_96:0_97:0_98:0_99:0_100:0_101:0_102:0_103:0_104:0_105:0_106:0_107:0_108:0_109:0_110:0_111:0_112:0_113:0_114:0_115:0_116:0_117:0_118:0_119:0_120:0_121:0_122:0_123:0_124:0_125:0_126:0_127:0_128:0_129:0_130:0_131:0_132:0_133:0_134:0_135:0_136:0_137:0_138:0_139:0_140:0_141:0_142:0_143:0_144:0_145:0_146:0_147:0_148:0_149:0_150:0_151:0_152:0_153:0_154:0_155:0_156:0_157:0_158:0_159:0_160:0 | X9: 1:0_2:0_3:0_4:0_5:0_6:0_7:0_8:0_9:0_10:0_11:0_12:0_13:0_14:0_15:0_16:0_17:0_18:0_19:0_20:0_21:0_22:0_23:0_24:0_25:0_26:0_27:0_28:0_29:0_30:0_31:0_32:0_33:0_34:0_35:0_36:0_37:0_38:0_39:0_40:0_41:0_42:0_43:0_44:0_45:0_46:0_47:0_48:0_49:0_50:0_51:0_52:0_53:0_54:0_55:0_56:0_57:0_58:0_59:0_60:0_61:0_62:0_63:0_64:0_65:0_66:0_67:0_68:0_69:0_70:0_71:0_72:0_73:0_74:0_75:0_76:0_77:0_78:0_79:0_80:0_81:0_82:0_83:0_84:0_85:0_86:0_87:0_88:0_89:0_90:0_91:0_92:0_93:0_94:0_95:0_96:0_97:0_98:0_99:0_100:0_101:0_102:0_103:0_104:0_105:0_106:0_107:0_108:0_109:0_110:0_111:0_112:0_113:0_114:0_115:0_116:0_117:0_118:0_119:0_120:0_121:0_122:0_123:0_124:0_125:0_126:0_127:0_128:0_129:0_130:0_131:0_132:0_133:0_134:0_135:0_136:0_137:0_138:0_139:0_140:0_141:0_142:0_143:0_144:0_145:0_146:0_147:0_148:0_149:0_150:0_151:0_152:0_153:0_154:0_155:0_156:0_157:0_158:0_159:0_160:0 | Y9: 20010001 | Z9: 0 | AA9: 1 | AB9: 0:2500_50:5000_80:10000_125:15000_160:30000 | AC9: 10000 | AD9: 10000 | AE9: 0 | AF9: 40 | AG9: 0 | AH9: 0 | AI9: 0 | AJ9: 0
A10: 10305 | B10: 1 | C10: 守卫6 | D10: 毒气猛士3 | E10: 未使用 | F10: 客户端资源组 | G10: 1 | H10: 2 | I10: 0:0 | J10: 0 | K10: 800001021 | L10: 800001021 | M10: 1 | N10: 13 | O10: 2 | P10: 8 | Q10: 0 | R10: 25 | S10: -3000 | T10: 1 | U10: 0 | V10: 1:0_2:0_3:0_4:0_5:0_6:0_7:0_8:0_9:0_10:0_11:0_12:0_13:0_14:0_15:0_16:0_17:0_18:0_19:0_20:0_21:0_22:0_23:0_24:0_25:0_26:0_27:0_28:0_29:0_30:0_31:0_32:0_33:0_34:0_35:0_36:0_37:0_38:0_39:0_40:0_41:0_42:0_43:0_44:0_45:0_46:0_47:0_48:0_49:0_50:0_51:0_52:0_53:0_54:0_55:0_56:0_57:0_58:0_59:0_60:0_61:0_62:0_63:0_64:0_65:0_66:0_67:0_68:0_69:0_70:0_71:0_72:0_73:0_74:0_75:0_76:0_77:0_78:0_79:0_80:0_81:0_82:0_83:0_84:0_85:0_86:0_87:0_88:0_89:0_90:0_91:0_92:0_93:0_94:0_95:0_96:0_97:0_98:0_99:0_100:0_101:0_102:0_103:0_104:0_105:0_106:0_107:0_108:0_109:0_110:0_111:0_112:0_113:0_114:0_115:0_116:0_117:0_118:0_119:0_120:0_121:0_122:0_123:0_124:0_125:0_126:0_127:0_128:0_129:0_130:0_131:0_132:0_133:0_134:0_135:0_136:0_137:0_138:0_139:0_140:0_141:0_142:0_143:0_144:0_145:0_146:0_147:0_148:0_149:0_150:0_151:0_152:0_153:0_154:0_155:0_156:0_157:0_158:0_159:0_160:0 | W10: 1:0_2:0_3:0_4:0_5:0_6:0_7:0_8:0_9:0_10:0_11:0_12:0_13:0_14:0_15:0_16:0_17:0_18:0_19:0_20:0_21:0_22:0_23:0_24:0_25:0_26:0_27:0_28:0_29:0_30:0_31:0_32:0_33:0_34:0_35:0_36:0_37:0_38:0_39:0_40:0_41:0_42:0_43:0_44:0_45:0_46:0_47:0_48:0_49:0_50:0_51:0_52:0_53:0_54:0_55:0_56:0_57:0_58:0_59:0_60:0_61:0_62:0_63:0_64:0_65:0_66:0_67:0_68:0_69:0_70:0_71:0_72:0_73:0_74:0_75:0_76:0_77:0_78:0_79:0_80:0_81:0_82:0_83:0_84:0_85:0_86:0_87:0_88:0_89:0_90:0_91:0_92:0_93:0_94:0_95:0_96:0_97:0_98:0_99:0_100:0_101:0_102:0_103:0_104:0_105:0_106:0_107:0_108:0_109:0_110:0_111:0_112:0_113:0_114:0_115:0_116:0_117:0_118:0_119:0_120:0_121:0_122:0_123:0_124:0_125:0_126:0_127:0_128:0_129:0_130:0_131:0_132:0_133:0_134:0_135:0_136:0_137:0_138:0_139:0_140:0_141:0_142:0_143:0_144:0_145:0_146:0_147:0_148:0_149:0_150:0_151:0_152:0_153:0_154:0_155:0_156:0_157:0_158:0_159:0_160:0 | X10: 1:0_2:0_3:0_4:0_5:0_6:0_7:0_8:0_9:0_10:0_11:0_12:0_13:0_14:0_15:0_16:0_17:0_18:0_19:0_20:0_21:0_22:0_23:0_24:0_25:0_26:0_27:0_28:0_29:0_30:0_31:0_32:0_33:0_34:0_35:0_36:0_37:0_38:0_39:0_40:0_41:0_42:0_43:0_44:0_45:0_46:0_47:0_48:0_49:0_50:0_51:0_52:0_53:0_54:0_55:0_56:0_57:0_58:0_59:0_60:0_61:0_62:0_63:0_64:0_65:0_66:0_67:0_68:0_69:0_70:0_71:0_72:0_73:0_74:0_75:0_76:0_77:0_78:0_79:0_80:0_81:0_82:0_83:0_84:0_85:0_86:0_87:0_88:0_89:0_90:0_91:0_92:0_93:0_94:0_95:0_96:0_97:0_98:0_99:0_100:0_101:0_102:0_103:0_104:0_105:0_106:0_107:0_108:0_109:0_110:0_111:0_112:0_113:0_114:0_115:0_116:0_117:0_118:0_119:0_120:0_121:0_122:0_123:0_124:0_125:0_126:0_127:0_128:0_129:0_130:0_131:0_132:0_133:0_134:0_135:0_136:0_137:0_138:0_139:0_140:0_141:0_142:0_143:0_144:0_145:0_146:0_147:0_148:0_149:0_150:0_151:0_152:0_153:0_154:0_155:0_156:0_157:0_158:0_159:0_160:0 | Y10: 20010001 | Z10: 0 | AA10: 1 | AB10: 0:2500_50:5000_80:10000_125:15000_160:30000 | AC10: 10000 | AD10: 10000 | AE10: 0 | AF10: 40 | AG10: 0 | AH10: 0 | AI10: 0 | AJ10: 0
A11: 10306 | B11: 1 | C11: 守卫7 | D11: 拳头怪3 | E11: 未使用 | F11: 客户端资源组 | G11: 1 | H11: 2 | I11: 0:0 | J11: 0 | K11: 800001021 | L11: 800001021 | M11: 1 | N11: 15 | O11: 2 | P11: 8 | Q11: 0 | R11: 25 | S11: -3000 | T11: 1 | U11: 0 | V11: 1:0_2:0_3:0_4:0_5:0_6:0_7:0_8:0_9:0_10:0_11:0_12:0_13:0_14:0_15:0_16:0_17:0_18:0_19:0_20:0_21:0_22:0_23:0_24:0_25:0_26:0_27:0_28:0_29:0_30:0_31:0_32:0_33:0_34:0_35:0_36:0_37:0_38:0_39:0_40:0_41:0_42:0_43:0_44:0_45:0_46:0_47:0_48:0_49:0_50:0_51:0_52:0_53:0_54:0_55:0_56:0_57:0_58:0_59:0_60:0_61:0_62:0_63:0_64:0_65:0_66:0_67:0_68:0_69:0_70:0_71:0_72:0_73:0_74:0_75:0_76:0_77:0_78:0_79:0_80:0_81:0_82:0_83:0_84:0_85:0_86:0_87:0_88:0_89:0_90:0_91:0_92:0_93:0_94:0_95:0_96:0_97:0_98:0_99:0_100:0_101:0_102:0_103:0_104:0_105:0_106:0_107:0_108:0_109:0_110:0_111:0_112:0_113:0_114:0_115:0_116:0_117:0_118:0_119:0_120:0_121:0_122:0_123:0_124:0_125:0_126:0_127:0_128:0_129:0_130:0_131:0_132:0_133:0_134:0_135:0_136:0_137:0_138:0_139:0_140:0_141:0_142:0_143:0_144:0_145:0_146:0_147:0_148:0_149:0_150:0_151:0_152:0_153:0_154:0_155:0_156:0_157:0_158:0_159:0_160:0 | W11: 1:0_2:0_3:0_4:0_5:0_6:0_7:0_8:0_9:0_10:0_11:0_12:0_13:0_14:0_15:0_16:0_17:0_18:0_19:0_20:0_21:0_22:0_23:0_24:0_25:0_26:0_27:0_28:0_29:0_30:0_31:0_32:0_33:0_34:0_35:0_36:0_37:0_38:0_39:0_40:0_41:0_42:0_43:0_44:0_45:0_46:0_47:0_48:0_49:0_50:0_51:0_52:0_53:0_54:0_55:0_56:0_57:0_58:0_59:0_60:0_61:0_62:0_63:0_64:0_65:0_66:0_67:0_68:0_69:0_70:0_71:0_72:0_73:0_74:0_75:0_76:0_77:0_78:0_79:0_80:0_81:0_82:0_83:0_84:0_85:0_86:0_87:0_88:0_89:0_90:0_91:0_92:0_93:0_94:0_95:0_96:0_97:0_98:0_99:0_100:0_101:0_102:0_103:0_104:0_105:0_106:0_107:0_108:0_109:0_110:0_111:0_112:0_113:0_114:0_115:0_116:0_117:0_118:0_119:0_120:0_121:0_122:0_123:0_124:0_125:0_126:0_127:0_128:0_129:0_130:0_131:0_132:0_133:0_134:0_135:0_136:0_137:0_138:0_139:0_140:0_141:0_142:0_143:0_144:0_145:0_146:0_147:0_148:0_149:0_150:0_151:0_152:0_153:0_154:0_155:0_156:0_157:0_158:0_159:0_160:0 | X11: 1:0_2:0_3:0_4:0_5:0_6:0_7:0_8:0_9:0_10:0_11:0_12:0_13:0_14:0_15:0_16:0_17:0_18:0_19:0_20:0_21:0_22:0_23:0_24:0_25:0_26:0_27:0_28:0_29:0_30:0_31:0_32:0_33:0_34:0_35:0_36:0_37:0_38:0_39:0_40:0_41:0_42:0_43:0_44:0_45:0_46:0_47:0_48:0_49:0_50:0_51:0_52:0_53:0_54:0_55:0_56:0_57:0_58:0_59:0_60:0_61:0_62:0_63:0_64:0_65:0_66:0_67:0_68:0_69:0_70:0_71:0_72:0_73:0_74:0_75:0_76:0_77:0_78:0_79:0_80:0_81:0_82:0_83:0_84:0_85:0_86:0_87:0_88:0_89:0_90:0_91:0_92:0_93:0_94:0_95:0_96:0_97:0_98:0_99:0_100:0_101:0_102:0_103:0_104:0_105:0_106:0_107:0_108:0_109:0_110:0_111:0_112:0_113:0_114:0_115:0_116:0_117:0_118:0_119:0_120:0_121:0_122:0_123:0_124:0_125:0_126:0_127:0_128:0_129:0_130:0_131:0_132:0_133:0_134:0_135:0_136:0_137:0_138:0_139:0_140:0_141:0_142:0_143:0_144:0_145:0_146:0_147:0_148:0_149:0_150:0_151:0_152:0_153:0_154:0_155:0_156:0_157:0_158:0_159:0_160:0 | Y11: 20010001 | Z11: 0 | AA11: 1 | AB11: 0:2500_50:5000_80:10000_125:15000_160:30000 | AC11: 10000 | AD11: 10000 | AE11: 0 | AF11: 40 | AG11: 0 | AH11: 0 | AI11: 0 | AJ11: 0
A12: 10307 | B12: 1 | C12: 守卫8 | D12: 第1关守卫 | E12: 未使用 | F12: 客户端资源组 | G12: 1 | H12: 2 | I12: 0:0 | J12: 0 | K12: 800001021 | L12: 800001021 | M12: 1 | N12: 35 | O12: 2 | P12: 8 | Q12: 0 | R12: 25 | S12: -3000 | T12: 1 | U12: 0 | V12: 1:0_2:0_3:0_4:0_5:0_6:0_7:0_8:0_9:0_10:0_11:0_12:0_13:0_14:0_15:0_16:0_17:0_18:0_19:0_20:0_21:0_22:0_23:0_24:0_25:0_26:0_27:0_28:0_29:0_30:0_31:0_32:0_33:0_34:0_35:0_36:0_37:0_38:0_39:0_40:0_41:0_42:0_43:0_44:0_45:0_46:0_47:0_48:0_49:0_50:0_51:0_52:0_53:0_54:0_55:0_56:0_57:0_58:0_59:0_60:0_61:0_62:0_63:0_64:0_65:0_66:0_67:0_68:0_69:0_70:0_71:0_72:0_73:0_74:0_75:0_76:0_77:0_78:0_79:0_80:0_81:0_82:0_83:0_84:0_85:0_86:0_87:0_88:0_89:0_90:0_91:0_92:0_93:0_94:0_95:0_96:0_97:0_98:0_99:0_100:0_101:0_102:0_103:0_104:0_105:0_106:0_107:0_108:0_109:0_110:0_111:0_112:0_113:0_114:0_115:0_116:0_117:0_118:0_119:0_120:0_121:0_122:0_123:0_124:0_125:0_126:0_127:0_128:0_129:0_130:0_131:0_132:0_133:0_134:0_135:0_136:0_137:0_138:0_139:0_140:0_141:0_142:0_143:0_144:0_145:0_146:0_147:0_148:0_149:0_150:0_151:0_152:0_153:0_154:0_155:0_156:0_157:0_158:0_159:0_160:0 | W12: 1:0_2:0_3:0_4:0_5:0_6:0_7:0_8:0_9:0_10:0_11:0_12:0_13:0_14:0_15:0_16:0_17:0_18:0_19:0_20:0_21:0_22:0_23:0_24:0_25:0_26:0_27:0_28:0_29:0_30:0_31:0_32:0_33:0_34:0_35:0_36:0_37:0_38:0_39:0_40:0_41:0_42:0_43:0_44:0_45:0_46:0_47:0_48:0_49:0_50:0_51:0_52:0_53:0_54:0_55:0_56:0_57:0_58:0_59:0_60:0_61:0_62:0_63:0_64:0_65:0_66:0_67:0_68:0_69:0_70:0_71:0_72:0_73:0_74:0_75:0_76:0_77:0_78:0_79:0_80:0_81:0_82:0_83:0_84:0_85:0_86:0_87:0_88:0_89:0_90:0_91:0_92:0_93:0_94:0_95:0_96:0_97:0_98:0_99:0_100:0_101:0_102:0_103:0_104:0_105:0_106:0_107:0_108:0_109:0_110:0_111:0_112:0_113:0_114:0_115:0_116:0_117:0_118:0_119:0_120:0_121:0_122:0_123:0_124:0_125:0_126:0_127:0_128:0_129:0_130:0_131:0_132:0_133:0_134:0_135:0_136:0_137:0_138:0_139:0_140:0_141:0_142:0_143:0_144:0_145:0_146:0_147:0_148:0_149:0_150:0_151:0_152:0_153:0_154:0_155:0_156:0_157:0_158:0_159:0_160:0 | X12: 1:0_2:0_3:0_4:0_5:0_6:0_7:0_8:0_9:0_10:0_11:0_12:0_13:0_14:0_15:0_16:0_17:0_18:0_19:0_20:0_21:0_22:0_23:0_24:0_25:0_26:0_27:0_28:0_29:0_30:0_31:0_32:0_33:0_34:0_35:0_36:0_37:0_38:0_39:0_40:0_41:0_42:0_43:0_44:0_45:0_46:0_47:0_48:0_49:0_50:0_51:0_52:0_53:0_54:0_55:0_56:0_57:0_58:0_59:0_60:0_61:0_62:0_63:0_64:0_65:0_66:0_67:0_68:0_69:0_70:0_71:0_72:0_73:0_74:0_75:0_76:0_77:0_78:0_79:0_80:0_81:0_82:0_83:0_84:0_85:0_86:0_87:0_88:0_89:0_90:0_91:0_92:0_93:0_94:0_95:0_96:0_97:0_98:0_99:0_100:0_101:0_102:0_103:0_104:0_105:0_106:0_107:0_108:0_109:0_110:0_111:0_112:0_113:0_114:0_115:0_116:0_117:0_118:0_119:0_120:0_121:0_122:0_123:0_124:0_125:0_126:0_127:0_128:0_129:0_130:0_131:0_132:0_133:0_134:0_135:0_136:0_137:0_138:0_139:0_140:0_141:0_142:0_143:0_144:0_145:0_146:0_147:0_148:0_149:0_150:0_151:0_152:0_153:0_154:0_155:0_156:0_157:0_158:0_159:0_160:0 | Y12: 20010001 | Z12: 0 | AA12: 1 | AB12: 0:2500_50:5000_80:10000_125:15000_160:30000 | AC12: 10000 | AD12: 10000 | AE12: 0 | AF12: 40 | AG12: 0 | AH12: 0 | AI12: 0 | AJ12: 0
A13: 10308 | B13: 1 | C13: 守卫9 | D13: 第1关守卫 | E13: 未使用 | F13: 客户端资源组 | G13: 1 | H13: 2 | I13: 0:0 | J13: 0 | K13: 800001021 | L13: 800001021 | M13: 1 | N13: 40 | O13: 2 | P13: 8 | Q13: 0 | R13: 25 | S13: -3000 | T13: 1 | U13: 0 | V13: 1:0_2:0_3:0_4:0_5:0_6:0_7:0_8:0_9:0_10:0_11:0_12:0_13:0_14:0_15:0_16:0_17:0_18:0_19:0_20:0_21:0_22:0_23:0_24:0_25:0_26:0_27:0_28:0_29:0_30:0_31:0_32:0_33:0_34:0_35:0_36:0_37:0_38:0_39:0_40:0_41:0_42:0_43:0_44:0_45:0_46:0_47:0_48:0_49:0_50:0_51:0_52:0_53:0_54:0_55:0_56:0_57:0_58:0_59:0_60:0_61:0_62:0_63:0_64:0_65:0_66:0_67:0_68:0_69:0_70:0_71:0_72:0_73:0_74:0_75:0_76:0_77:0_78:0_79:0_80:0_81:0_82:0_83:0_84:0_85:0_86:0_87:0_88:0_89:0_90:0_91:0_92:0_93:0_94:0_95:0_96:0_97:0_98:0_99:0_100:0_101:0_102:0_103:0_104:0_105:0_106:0_107:0_108:0_109:0_110:0_111:0_112:0_113:0_114:0_115:0_116:0_117:0_118:0_119:0_120:0_121:0_122:0_123:0_124:0_125:0_126:0_127:0_128:0_129:0_130:0_131:0_132:0_133:0_134:0_135:0_136:0_137:0_138:0_139:0_140:0_141:0_142:0_143:0_144:0_145:0_146:0_147:0_148:0_149:0_150:0_151:0_152:0_153:0_154:0_155:0_156:0_157:0_158:0_159:0_160:0 | W13: 1:0_2:0_3:0_4:0_5:0_6:0_7:0_8:0_9:0_10:0_11:0_12:0_13:0_14:0_15:0_16:0_17:0_18:0_19:0_20:0_21:0_22:0_23:0_24:0_25:0_26:0_27:0_28:0_29:0_30:0_31:0_32:0_33:0_34:0_35:0_36:0_37:0_38:0_39:0_40:0_41:0_42:0_43:0_44:0_45:0_46:0_47:0_48:0_49:0_50:0_51:0_52:0_53:0_54:0_55:0_56:0_57:0_58:0_59:0_60:0_61:0_62:0_63:0_64:0_65:0_66:0_67:0_68:0_69:0_70:0_71:0_72:0_73:0_74:0_75:0_76:0_77:0_78:0_79:0_80:0_81:0_82:0_83:0_84:0_85:0_86:0_87:0_88:0_89:0_90:0_91:0_92:0_93:0_94:0_95:0_96:0_97:0_98:0_99:0_100:0_101:0_102:0_103:0_104:0_105:0_106:0_107:0_108:0_109:0_110:0_111:0_112:0_113:0_114:0_115:0_116:0_117:0_118:0_119:0_120:0_121:0_122:0_123:0_124:0_125:0_126:0_127:0_128:0_129:0_130:0_131:0_132:0_133:0_134:0_135:0_136:0_137:0_138:0_139:0_140:0_141:0_142:0_143:0_144:0_145:0_146:0_147:0_148:0_149:0_150:0_151:0_152:0_153:0_154:0_155:0_156:0_157:0_158:0_159:0_160:0 | X13: 1:0_2:0_3:0_4:0_5:0_6:0_7:0_8:0_9:0_10:0_11:0_12:0_13:0_14:0_15:0_16:0_17:0_18:0_19:0_20:0_21:0_22:0_23:0_24:0_25:0_26:0_27:0_28:0_29:0_30:0_31:0_32:0_33:0_34:0_35:0_36:0_37:0_38:0_39:0_40:0_41:0_42:0_43:0_44:0_45:0_46:0_47:0_48:0_49:0_50:0_51:0_52:0_53:0_54:0_55:0_56:0_57:0_58:0_59:0_60:0_61:0_62:0_63:0_64:0_65:0_66:0_67:0_68:0_69:0_70:0_71:0_72:0_73:0_74:0_75:0_76:0_77:0_78:0_79:0_80:0_81:0_82:0_83:0_84:0_85:0_86:0_87:0_88:0_89:0_90:0_91:0_92:0_93:0_94:0_95:0_96:0_97:0_98:0_99:0_100:0_101:0_102:0_103:0_104:0_105:0_106:0_107:0_108:0_109:0_110:0_111:0_112:0_113:0_114:0_115:0_116:0_117:0_118:0_119:0_120:0_121:0_122:0_123:0_124:0_125:0_126:0_127:0_128:0_129:0_130:0_131:0_132:0_133:0_134:0_135:0_136:0_137:0_138:0_139:0_140:0_141:0_142:0_143:0_144:0_145:0_146:0_147:0_148:0_149:0_150:0_151:0_152:0_153:0_154:0_155:0_156:0_157:0_158:0_159:0_160:0 | Y13: 20010001 | Z13: 0 | AA13: 1 | AB13: 0:2500_50:5000_80:10000_125:15000_160:30000 | AC13: 10000 | AD13: 10000 | AE13: 0 | AF13: 40 | AG13: 0 | AH13: 0 | AI13: 0 | AJ13: 0
A14: 10309 | B14: 1 | C14: 守卫10 | D14: 第1关守卫 | E14: 未使用 | F14: 客户端资源组 | G14: 1 | H14: 2 | I14: 0:0 | J14: 0 | K14: 800001021 | L14: 800001021 | M14: 1 | N14: 90 | O14: 2 | P14: 8 | Q14: 0 | R14: 25 | S14: -3000 | T14: 1 | U14: 0 | V14: 1:0_2:0_3:0_4:0_5:0_6:0_7:0_8:0_9:0_10:0_11:0_12:0_13:0_14:0_15:0_16:0_17:0_18:0_19:0_20:0_21:0_22:0_23:0_24:0_25:0_26:0_27:0_28:0_29:0_30:0_31:0_32:0_33:0_34:0_35:0_36:0_37:0_38:0_39:0_40:0_41:0_42:0_43:0_44:0_45:0_46:0_47:0_48:0_49:0_50:0_51:0_52:0_53:0_54:0_55:0_56:0_57:0_58:0_59:0_60:0_61:0_62:0_63:0_64:0_65:0_66:0_67:0_68:0_69:0_70:0_71:0_72:0_73:0_74:0_75:0_76:0_77:0_78:0_79:0_80:0_81:0_82:0_83:0_84:0_85:0_86:0_87:0_88:0_89:0_90:0_91:0_92:0_93:0_94:0_95:0_96:0_97:0_98:0_99:0_100:0_101:0_102:0_103:0_104:0_105:0_106:0_107:0_108:0_109:0_110:0_111:0_112:0_113:0_114:0_115:0_116:0_117:0_118:0_119:0_120:0_121:0_122:0_123:0_124:0_125:0_126:0_127:0_128:0_129:0_130:0_131:0_132:0_133:0_134:0_135:0_136:0_137:0_138:0_139:0_140:0_141:0_142:0_143:0_144:0_145:0_146:0_147:0_148:0_149:0_150:0_151:0_152:0_153:0_154:0_155:0_156:0_157:0_158:0_159:0_160:0 | W14: 1:0_2:0_3:0_4:0_5:0_6:0_7:0_8:0_9:0_10:0_11:0_12:0_13:0_14:0_15:0_16:0_17:0_18:0_19:0_20:0_21:0_22:0_23:0_24:0_25:0_26:0_27:0_28:0_29:0_30:0_31:0_32:0_33:0_34:0_35:0_36:0_37:0_38:0_39:0_40:0_41:0_42:0_43:0_44:0_45:0_46:0_47:0_48:0_49:0_50:0_51:0_52:0_53:0_54:0_55:0_56:0_57:0_58:0_59:0_60:0_61:0_62:0_63:0_64:0_65:0_66:0_67:0_68:0_69:0_70:0_71:0_72:0_73:0_74:0_75:0_76:0_77:0_78:0_79:0_80:0_81:0_82:0_83:0_84:0_85:0_86:0_87:0_88:0_89:0_90:0_91:0_92:0_93:0_94:0_95:0_96:0_97:0_98:0_99:0_100:0_101:0_102:0_103:0_104:0_105:0_106:0_107:0_108:0_109:0_110:0_111:0_112:0_113:0_114:0_115:0_116:0_117:0_118:0_119:0_120:0_121:0_122:0_123:0_124:0_125:0_126:0_127:0_128:0_129:0_130:0_131:0_132:0_133:0_134:0_135:0_136:0_137:0_138:0_139:0_140:0_141:0_142:0_143:0_144:0_145:0_146:0_147:0_148:0_149:0_150:0_151:0_152:0_153:0_154:0_155:0_156:0_157:0_158:0_159:0_160:0 | X14: 1:0_2:0_3:0_4:0_5:0_6:0_7:0_8:0_9:0_10:0_11:0_12:0_13:0_14:0_15:0_16:0_17:0_18:0_19:0_20:0_21:0_22:0_23:0_24:0_25:0_26:0_27:0_28:0_29:0_30:0_31:0_32:0_33:0_34:0_35:0_36:0_37:0_38:0_39:0_40:0_41:0_42:0_43:0_44:0_45:0_46:0_47:0_48:0_49:0_50:0_51:0_52:0_53:0_54:0_55:0_56:0_57:0_58:0_59:0_60:0_61:0_62:0_63:0_64:0_65:0_66:0_67:0_68:0_69:0_70:0_71:0_72:0_73:0_74:0_75:0_76:0_77:0_78:0_79:0_80:0_81:0_82:0_83:0_84:0_85:0_86:0_87:0_88:0_89:0_90:0_91:0_92:0_93:0_94:0_95:0_96:0_97:0_98:0_99:0_100:0_101:0_102:0_103:0_104:0_105:0_106:0_107:0_108:0_109:0_110:0_111:0_112:0_113:0_114:0_115:0_116:0_117:0_118:0_119:0_120:0_121:0_122:0_123:0_124:0_125:0_126:0_127:0_128:0_129:0_130:0_131:0_132:0_133:0_134:0_135:0_136:0_137:0_138:0_139:0_140:0_141:0_142:0_143:0_144:0_145:0_146:0_147:0_148:0_149:0_150:0_151:0_152:0_153:0_154:0_155:0_156:0_157:0_158:0_159:0_160:0 | Y14: 20010001 | Z14: 0 | AA14: 1 | AB14: 0:2500_50:5000_80:10000_125:15000_160:30000 | AC14: 10000 | AD14: 10000 | AE14: 0 | AF14: 40 | AG14: 0 | AH14: 0 | AI14: 0 | AJ14: 0
A15: 10310 | B15: 1 | C15: 守卫11 | D15: 第1关守卫 | E15: 未使用 | F15: 客户端资源组 | G15: 1 | H15: 2 | I15: 0:0 | J15: 0 | K15: 800001021 | L15: 800001021 | M15: 1 | N15: 100 | O15: 2 | P15: 8 | Q15: 0 | R15: 25 | S15: -3000 | T15: 1 | U15: 0 | V15: 1:0_2:0_3:0_4:0_5:0_6:0_7:0_8:0_9:0_10:0_11:0_12:0_13:0_14:0_15:0_16:0_17:0_18:0_19:0_20:0_21:0_22:0_23:0_24:0_25:0_26:0_27:0_28:0_29:0_30:0_31:0_32:0_33:0_34:0_35:0_36:0_37:0_38:0_39:0_40:0_41:0_42:0_43:0_44:0_45:0_46:0_47:0_48:0_49:0_50:0_51:0_52:0_53:0_54:0_55:0_56:0_57:0_58:0_59:0_60:0_61:0_62:0_63:0_64:0_65:0_66:0_67:0_68:0_69:0_70:0_71:0_72:0_73:0_74:0_75:0_76:0_77:0_78:0_79:0_80:0_81:0_82:0_83:0_84:0_85:0_86:0_87:0_88:0_89:0_90:0_91:0_92:0_93:0_94:0_95:0_96:0_97:0_98:0_99:0_100:0_101:0_102:0_103:0_104:0_105:0_106:0_107:0_108:0_109:0_110:0_111:0_112:0_113:0_114:0_115:0_116:0_117:0_118:0_119:0_120:0_121:0_122:0_123:0_124:0_125:0_126:0_127:0_128:0_129:0_130:0_131:0_132:0_133:0_134:0_135:0_136:0_137:0_138:0_139:0_140:0_141:0_142:0_143:0_144:0_145:0_146:0_147:0_148:0_149:0_150:0_151:0_152:0_153:0_154:0_155:0_156:0_157:0_158:0_159:0_160:0 | W15: 1:0_2:0_3:0_4:0_5:0_6:0_7:0_8:0_9:0_10:0_11:0_12:0_13:0_14:0_15:0_16:0_17:0_18:0_19:0_20:0_21:0_22:0_23:0_24:0_25:0_26:0_27:0_28:0_29:0_30:0_31:0_32:0_33:0_34:0_35:0_36:0_37:0_38:0_39:0_40:0_41:0_42:0_43:0_44:0_45:0_46:0_47:0_48:0_49:0_50:0_51:0_52:0_53:0_54:0_55:0_56:0_57:0_58:0_59:0_60:0_61:0_62:0_63:0_64:0_65:0_66:0_67:0_68:0_69:0_70:0_71:0_72:0_73:0_74:0_75:0_76:0_77:0_78:0_79:0_80:0_81:0_82:0_83:0_84:0_85:0_86:0_87:0_88:0_89:0_90:0_91:0_92:0_93:0_94:0_95:0_96:0_97:0_98:0_99:0_100:0_101:0_102:0_103:0_104:0_105:0_106:0_107:0_108:0_109:0_110:0_111:0_112:0_113:0_114:0_115:0_116:0_117:0_118:0_119:0_120:0_121:0_122:0_123:0_124:0_125:0_126:0_127:0_128:0_129:0_130:0_131:0_132:0_133:0_134:0_135:0_136:0_137:0_138:0_139:0_140:0_141:0_142:0_143:0_144:0_145:0_146:0_147:0_148:0_149:0_150:0_151:0_152:0_153:0_154:0_155:0_156:0_157:0_158:0_159:0_160:0 | X15: 1:0_2:0_3:0_4:0_5:0_6:0_7:0_8:0_9:0_10:0_11:0_12:0_13:0_14:0_15:0_16:0_17:0_18:0_19:0_20:0_21:0_22:0_23:0_24:0_25:0_26:0_27:0_28:0_29:0_30:0_31:0_32:0_33:0_34:0_35:0_36:0_37:0_38:0_39:0_40:0_41:0_42:0_43:0_44:0_45:0_46:0_47:0_48:0_49:0_50:0_51:0_52:0_53:0_54:0_55:0_56:0_57:0_58:0_59:0_60:0_61:0_62:0_63:0_64:0_65:0_66:0_67:0_68:0_69:0_70:0_71:0_72:0_73:0_74:0_75:0_76:0_77:0_78:0_79:0_80:0_81:0_82:0_83:0_84:0_85:0_86:0_87:0_88:0_89:0_90:0_91:0_92:0_93:0_94:0_95:0_96:0_97:0_98:0_99:0_100:0_101:0_102:0_103:0_104:0_105:0_106:0_107:0_108:0_109:0_110:0_111:0_112:0_113:0_114:0_115:0_116:0_117:0_118:0_119:0_120:0_121:0_122:0_123:0_124:0_125:0_126:0_127:0_128:0_129:0_130:0_131:0_132:0_133:0_134:0_135:0_136:0_137:0_138:0_139:0_140:0_141:0_142:0_143:0_144:0_145:0_146:0_147:0_148:0_149:0_150:0_151:0_152:0_153:0_154:0_155:0_156:0_157:0_158:0_159:0_160:0 | Y15: 20010001 | Z15: 0 | AA15: 1 | AB15: 0:2500_50:5000_80:10000_125:15000_160:30000 | AC15: 10000 | AD15: 10000 | AE15: 0 | AF15: 40 | AG15: 0 | AH15: 0 | AI15: 0 | AJ15: 0
A16: 10401 | B16: 1 | C16: 卫兵 | D16: 雷霆魔头3 | E16: 未使用 | F16: 客户端资源组 | G16: 1 | H16: 2 | I16: 0:0 | J16: 0 | K16: 800001021 | L16: 800001021 | M16: 1 | N16: 100 | O16: 2 | P16: 8 | Q16: 0 | R16: 25 | S16: -3000 | T16: 1 | U16: 0 | V16: 1:0_2:0_3:0_4:0_5:0_6:0_7:0_8:0_9:0_10:0_11:0_12:0_13:0_14:0_15:0_16:0_17:0_18:0_19:0_20:0_21:0_22:0_23:0_24:0_25:0_26:0_27:0_28:0_29:0_30:0_31:0_32:0_33:0_34:0_35:0_36:0_37:0_38:0_39:0_40:0_41:0_42:0_43:0_44:0_45:0_46:0_47:0_48:0_49:0_50:0_51:0_52:0_53:0_54:0_55:0_56:0_57:0_58:0_59:0_60:0_61:0_62:0_63:0_64:0_65:0_66:0_67:0_68:0_69:0_70:0_71:0_72:0_73:0_74:0_75:0_76:0_77:0_78:0_79:0_80:0_81:0_82:0_83:0_84:0_85:0_86:0_87:0_88:0_89:0_90:0_91:0_92:0_93:0_94:0_95:0_96:0_97:0_98:0_99:0_100:0_101:0_102:0_103:0_104:0_105:0_106:0_107:0_108:0_109:0_110:0_111:0_112:0_113:0_114:0_115:0_116:0_117:0_118:0_119:0_120:0_121:0_122:0_123:0_124:0_125:0_126:0_127:0_128:0_129:0_130:0_131:0_132:0_133:0_134:0_135:0_136:0_137:0_138:0_139:0_140:0_141:0_142:0_143:0_144:0_145:0_146:0_147:0_148:0_149:0_150:0_151:0_152:0_153:0_154:0_155:0_156:0_157:0_158:0_159:0_160:0 | W16: 1:0_2:0_3:0_4:0_5:0_6:0_7:0_8:0_9:0_10:0_11:0_12:0_13:0_14:0_15:0_16:0_17:0_18:0_19:0_20:0_21:0_22:0_23:0_24:0_25:0_26:0_27:0_28:0_29:0_30:0_31:0_32:0_33:0_34:0_35:0_36:0_37:0_38:0_39:0_40:0_41:0_42:0_43:0_44:0_45:0_46:0_47:0_48:0_49:0_50:0_51:0_52:0_53:0_54:0_55:0_56:0_57:0_58:0_59:0_60:0_61:0_62:0_63:0_64:0_65:0_66:0_67:0_68:0_69:0_70:0_71:0_72:0_73:0_74:0_75:0_76:0_77:0_78:0_79:0_80:0_81:0_82:0_83:0_84:0_85:0_86:0_87:0_88:0_89:0_90:0_91:0_92:0_93:0_94:0_95:0_96:0_97:0_98:0_99:0_100:0_101:0_102:0_103:0_104:0_105:0_106:0_107:0_108:0_109:0_110:0_111:0_112:0_113:0_114:0_115:0_116:0_117:0_118:0_119:0_120:0_121:0_122:0_123:0_124:0_125:0_126:0_127:0_128:0_129:0_130:0_131:0_132:0_133:0_134:0_135:0_136:0_137:0_138:0_139:0_140:0_141:0_142:0_143:0_144:0_145:0_146:0_147:0_148:0_149:0_150:0_151:0_152:0_153:0_154:0_155:0_156:0_157:0_158:0_159:0_160:0 | X16: 1:0_2:0_3:0_4:0_5:0_6:0_7:0_8:0_9:0_10:0_11:0_12:0_13:0_14:0_15:0_16:0_17:0_18:0_19:0_20:0_21:0_22:0_23:0_24:0_25:0_26:0_27:0_28:0_29:0_30:0_31:0_32:0_33:0_34:0_35:0_36:0_37:0_38:0_39:0_40:0_41:0_42:0_43:0_44:0_45:0_46:0_47:0_48:0_49:0_50:0_51:0_52:0_53:0_54:0_55:0_56:0_57:0_58:0_59:0_60:0_61:0_62:0_63:0_64:0_65:0_66:0_67:0_68:0_69:0_70:0_71:0_72:0_73:0_74:0_75:0_76:0_77:0_78:0_79:0_80:0_81:0_82:0_83:0_84:0_85:0_86:0_87:0_88:0_89:0_90:0_91:0_92:0_93:0_94:0_95:0_96:0_97:0_98:0_99:0_100:0_101:0_102:0_103:0_104:0_105:0_106:0_107:0_108:0_109:0_110:0_111:0_112:0_113:0_114:0_115:0_116:0_117:0_118:0_119:0_120:0_121:0_122:0_123:0_124:0_125:0_126:0_127:0_128:0_129:0_130:0_131:0_132:0_133:0_134:0_135:0_136:0_137:0_138:0_139:0_140:0_141:0_142:0_143:0_144:0_145:0_146:0_147:0_148:0_149:0_150:0_151:0_152:0_153:0_154:0_155:0_156:0_157:0_158:0_159:0_160:0 | Y16: 20010001 | Z16: 0 | AA16: 1 | AB16: 0:2500_2:5000_3:10000_5:15000_6:30000 | AC16: 10000 | AD16: 10000 | AE16: 0 | AF16: 40 | AG16: 0 | AH16: 0 | AI16: 0 | AJ16: 0
... A18: 10403 | B18: 1 | C18: 卫兵 | D18: 雷霆魔头3 | E18: 未使用 | F18: 客户端资源组 | G18: 1 | H18: 2 | I18: 0:0 | J18: 0 | K18: 800001021 | L18: 800001021 | M18: 1 | N18: 100 | O18: 2 | P18: 8 | Q18: 0 | R18: 25 | S18: -3000 | T18: 1 | U18: 0 | V18: 1:0_2:0_3:0_4:0_5:0_6:0_7:0_8:0_9:0_10:0_11:0_12:0_13:0_14:0_15:0_16:0_17:0_18:0_19:0_20:0_21:0_22:0_23:0_24:0_25:0_26:0_27:0_28:0_29:0_30:0_31:0_32:0_33:0_34:0_35:0_36:0_37:0_38:0_39:0_40:0_41:0_42:0_43:0_44:0_45:0_46:0_47:0_48:0_49:0_50:0_51:0_52:0_53:0_54:0_55:0_56:0_57:0_58:0_59:0_60:0_61:0_62:0_63:0_64:0_65:0_66:0_67:0_68:0_69:0_70:0_71:0_72:0_73:0_74:0_75:0_76:0_77:0_78:0_79:0_80:0_81:0_82:0_83:0_84:0_85:0_86:0_87:0_88:0_89:0_90:0_91:0_92:0_93:0_94:0_95:0_96:0_97:0_98:0_99:0_100:0_101:0_102:0_103:0_104:0_105:0_106:0_107:0_108:0_109:0_110:0_111:0_112:0_113:0_114:0_115:0_116:0_117:0_118:0_119:0_120:0_121:0_122:0_123:0_124:0_125:0_126:0_127:0_128:0_129:0_130:0_131:0_132:0_133:0_134:0_135:0_136:0_137:0_138:0_139:0_140:0_141:0_142:0_143:0_144:0_145:0_146:0_147:0_148:0_149:0_150:0_151:0_152:0_153:0_154:0_155:0_156:0_157:0_158:0_159:0_160:0 | W18: 1:0_2:0_3:0_4:0_5:0_6:0_7:0_8:0_9:0_10:0_11:0_12:0_13:0_14:0_15:0_16:0_17:0_18:0_19:0_20:0_21:0_22:0_23:0_24:0_25:0_26:0_27:0_28:0_29:0_30:0_31:0_32:0_33:0_34:0_35:0_36:0_37:0_38:0_39:0_40:0_41:0_42:0_43:0_44:0_45:0_46:0_47:0_48:0_49:0_50:0_51:0_52:0_53:0_54:0_55:0_56:0_57:0_58:0_59:0_60:0_61:0_62:0_63:0_64:0_65:0_66:0_67:0_68:0_69:0_70:0_71:0_72:0_73:0_74:0_75:0_76:0_77:0_78:0_79:0_80:0_81:0_82:0_83:0_84:0_85:0_86:0_87:0_88:0_89:0_90:0_91:0_92:0_93:0_94:0_95:0_96:0_97:0_98:0_99:0_100:0_101:0_102:0_103:0_104:0_105:0_106:0_107:0_108:0_109:0_110:0_111:0_112:0_113:0_114:0_115:0_116:0_117:0_118:0_119:0_120:0_121:0_122:0_123:0_124:0_125:0_126:0_127:0_128:0_129:0_130:0_131:0_132:0_133:0_134:0_135:0_136:0_137:0_138:0_139:0_140:0_141:0_142:0_143:0_144:0_145:0_146:0_147:0_148:0_149:0_150:0_151:0_152:0_153:0_154:0_155:0_156:0_157:0_158:0_159:0_160:0 | X18: 1:0_2:0_3:0_4:0_5:0_6:0_7:0_8:0_9:0_10:0_11:0_12:0_13:0_14:0_15:0_16:0_17:0_18:0_19:0_20:0_21:0_22:0_23:0_24:0_25:0_26:0_27:0_28:0_29:0_30:0_31:0_32:0_33:0_34:0_35:0_36:0_37:0_38:0_39:0_40:0_41:0_42:0_43:0_44:0_45:0_46:0_47:0_48:0_49:0_50:0_51:0_52:0_53:0_54:0_55:0_56:0_57:0_58:0_59:0_60:0_61:0_62:0_63:0_64:0_65:0_66:0_67:0_68:0_69:0_70:0_71:0_72:0_73:0_74:0_75:0_76:0_77:0_78:0_79:0_80:0_81:0_82:0_83:0_84:0_85:0_86:0_87:0_88:0_89:0_90:0_91:0_92:0_93:0_94:0_95:0_96:0_97:0_98:0_99:0_100:0_101:0_102:0_103:0_104:0_105:0_106:0_107:0_108:0_109:0_110:0_111:0_112:0_113:0_114:0_115:0_116:0_117:0_118:0_119:0_120:0_121:0_122:0_123:0_124:0_125:0_126:0_127:0_128:0_129:0_130:0_131:0_132:0_133:0_134:0_135:0_136:0_137:0_138:0_139:0_140:0_141:0_142:0_143:0_144:0_145:0_146:0_147:0_148:0_149:0_150:0_151:0_152:0_153:0_154:0_155:0_156:0_157:0_158:0_159:0_160:0 | Y18: 20010001 | Z18: 0 | AA18: 1 | AB18: 0:2500_2:5000_3:10000_5:15000_6:30000 | AC18: 10000 | AD18: 10000 | AE18: 0 | AF18: 40 | AG18: 0 | AH18: 0 | AI18: 0 | AJ18: 0
A19: 20201 | B19: 2 | C19: 守卫1 | D19: 雷霆魔头3 | E19: 未使用 | F19: 客户端资源组 | G19: 2 | H19: 2 | I19: 0:0 | J19: 0 | K19: 雷霆魔头 | L19: 800001021 | M19: 2 | N19: 240 | O19: 1 | P19: 12 | Q19: 0 | R19: 36 | S19: -3000 | T19: 1 | U19: 80 | V19: 1:0_2:0_3:0_4:0_5:0_6:0_7:0_8:0_9:0_10:0_11:0_12:0_13:0_14:0_15:0_16:0_17:0_18:0_19:0_20:0_21:0_22:0_23:0_24:0_25:0_26:0_27:0_28:0_29:0_30:0_31:0_32:0_33:0_34:0_35:0_36:0_37:0_38:0_39:0_40:0_41:0_42:0_43:0_44:0_45:0_46:0_47:0_48:0_49:0_50:0_51:0_52:0_53:0_54:0_55:0_56:0_57:0_58:0_59:0_60:0_61:0_62:0_63:0_64:0_65:0_66:0_67:0_68:0_69:0_70:0_71:0_72:0_73:0_74:0_75:0_76:0_77:0_78:0_79:0_80:0_81:0_82:0_83:0_84:0_85:0_86:0_87:0_88:0_89:0_90:0_91:0_92:0_93:0_94:0_95:0_96:0_97:0_98:0_99:0_100:0_101:0_102:0_103:0_104:0_105:0_106:0_107:0_108:0_109:0_110:0_111:0_112:0_113:0_114:0_115:0_116:0_117:0_118:0_119:0_120:0_121:0_122:0_123:0_124:0_125:0_126:0_127:0_128:0_129:0_130:0_131:0_132:0_133:0_134:0_135:0_136:0_137:0_138:0_139:0_140:0_141:0_142:0_143:0_144:0_145:0_146:0_147:0_148:0_149:0_150:0_151:0_152:0_153:0_154:0_155:0_156:0_157:0_158:0_159:0_160:0 | W19: 1:0_2:0_3:0_4:0_5:0_6:0_7:0_8:0_9:0_10:0_11:0_12:0_13:0_14:0_15:0_16:0_17:0_18:0_19:0_20:0_21:0_22:0_23:0_24:0_25:0_26:0_27:0_28:0_29:0_30:0_31:0_32:0_33:0_34:0_35:0_36:0_37:0_38:0_39:0_40:0_41:0_42:0_43:0_44:0_45:0_46:0_47:0_48:0_49:0_50:0_51:0_52:0_53:0_54:0_55:0_56:0_57:0_58:0_59:0_60:0_61:0_62:0_63:0_64:0_65:0_66:0_67:0_68:0_69:0_70:0_71:0_72:0_73:0_74:0_75:0_76:0_77:0_78:0_79:0_80:0_81:0_82:0_83:0_84:0_85:0_86:0_87:0_88:0_89:0_90:0_91:0_92:0_93:0_94:0_95:0_96:0_97:0_98:0_99:0_100:0_101:0_102:0_103:0_104:0_105:0_106:0_107:0_108:0_109:0_110:0_111:0_112:0_113:0_114:0_115:0_116:0_117:0_118:0_119:0_120:0_121:0_122:0_123:0_124:0_125:0_126:0_127:0_128:0_129:0_130:0_131:0_132:0_133:0_134:0_135:0_136:0_137:0_138:0_139:0_140:0_141:0_142:0_143:0_144:0_145:0_146:0_147:0_148:0_149:0_150:0_151:0_152:0_153:0_154:0_155:0_156:0_157:0_158:0_159:0_160:0 | X19: 1:2_2:635_3:635_4:635_5:405_6:405_7:315_8:315_9:315_10:315_11:315_12:315_13:315_14:315_15:315_16:315_17:315_18:315_19:315_20:315_21:315_22:315_23:315_24:315_25:315_26:315_27:315_28:315_29:315_30:315_31:315_32:315_33:315_34:315_35:315_36:315_37:315_38:315_39:315_40:315_41:315_42:315_43:315_44:315_45:315_46:315_47:315_48:315_49:315_50:315_51:315_52:315_53:315_54:315_55:315_56:315_57:315_58:315_59:315_60:315_61:315_62:315_63:315_64:315_65:315_66:315_67:315_68:315_69:315_70:315_71:315_72:315_73:315_74:315_75:315_76:315_77:315_78:315_79:315_80:315_81:315_82:315_83:315_84:315_85:315_86:315_87:315_88:315_89:315_90:315_91:315_92:315_93:315_94:315_95:315_96:315_97:315_98:315_99:315_100:315_101:0_102:0_103:0_104:0_105:0_106:0_107:0_108:0_109:0_110:0_111:0_112:0_113:0_114:0_115:0_116:0_117:0_118:0_119:0_120:0_121:0_122:0_123:0_124:0_125:0_126:0_127:0_128:0_129:0_130:0_131:0_132:0_133:0_134:0_135:0_136:0_137:0_138:0_139:0_140:0_141:0_142:0_143:0_144:0_145:0_146:0_147:0_148:0_149:0_150:0_151:0_152:0_153:0_154:0_155:0_156:0_157:0_158:0_159:0_160:0 | Y19: 20010001 | Z19: 0 | AA19: 1 | AB19: 0:2500_50:5000_80:10000_125:15000_160:30000 | AC19: 10000 | AD19: 10000 | AE19: 25010001 | AF19: 40 | AG19: 0 | AH19: 0 | AI19: 0 | AJ19: 0
A20: 20301 | B20: 2 | C20: 守卫2 | D20: 野猪怪 | E20: 未使用 | F20: 客户端资源组 | G20: 2 | H20: 2 | I20: 0:0 | J20: 0 | K20: 獠牙霸主 | L20: 800001021 | M20: 2 | N20: 300 | O20: 2 | P20: 13 | Q20: 0 | R20: 40 | S20: -3000 | T20: 1 | U20: 80 | V20: 1:0_2:0_3:0_4:0_5:0_6:0_7:0_8:0_9:0_10:0_11:0_12:0_13:0_14:0_15:0_16:0_17:0_18:0_19:0_20:0_21:0_22:0_23:0_24:0_25:0_26:0_27:0_28:0_29:0_30:0_31:0_32:0_33:0_34:0_35:0_36:0_37:0_38:0_39:0_40:0_41:0_42:0_43:0_44:0_45:0_46:0_47:0_48:0_49:0_50:0_51:0_52:0_53:0_54:0_55:0_56:0_57:0_58:0_59:0_60:0_61:0_62:0_63:0_64:0_65:0_66:0_67:0_68:0_69:0_70:0_71:0_72:0_73:0_74:0_75:0_76:0_77:0_78:0_79:0_80:0_81:0_82:0_83:0_84:0_85:0_86:0_87:0_88:0_89:0_90:0_91:0_92:0_93:0_94:0_95:0_96:0_97:0_98:0_99:0_100:0_101:0_102:0_103:0_104:0_105:0_106:0_107:0_108:0_109:0_110:0_111:0_112:0_113:0_114:0_115:0_116:0_117:0_118:0_119:0_120:0_121:0_122:0_123:0_124:0_125:0_126:0_127:0_128:0_129:0_130:0_131:0_132:0_133:0_134:0_135:0_136:0_137:0_138:0_139:0_140:0_141:0_142:0_143:0_144:0_145:0_146:0_147:0_148:0_149:0_150:0_151:0_152:0_153:0_154:0_155:0_156:0_157:0_158:0_159:0_160:0 | W20: 1:0_2:0_3:0_4:0_5:0_6:0_7:0_8:0_9:0_10:0_11:0_12:0_13:0_14:0_15:0_16:0_17:0_18:0_19:0_20:0_21:0_22:0_23:0_24:0_25:0_26:0_27:0_28:0_29:0_30:0_31:0_32:0_33:0_34:0_35:0_36:0_37:0_38:0_39:0_40:0_41:0_42:0_43:0_44:0_45:0_46:0_47:0_48:0_49:0_50:0_51:0_52:0_53:0_54:0_55:0_56:0_57:0_58:0_59:0_60:0_61:0_62:0_63:0_64:0_65:0_66:0_67:0_68:0_69:0_70:0_71:0_72:0_73:0_74:0_75:0_76:0_77:0_78:0_79:0_80:0_81:0_82:0_83:0_84:0_85:0_86:0_87:0_88:0_89:0_90:0_91:0_92:0_93:0_94:0_95:0_96:0_97:0_98:0_99:0_100:0_101:0_102:0_103:0_104:0_105:0_106:0_107:0_108:0_109:0_110:0_111:0_112:0_113:0_114:0_115:0_116:0_117:0_118:0_119:0_120:0_121:0_122:0_123:0_124:0_125:0_126:0_127:0_128:0_129:0_130:0_131:0_132:0_133:0_134:0_135:0_136:0_137:0_138:0_139:0_140:0_141:0_142:0_143:0_144:0_145:0_146:0_147:0_148:0_149:0_150:0_151:0_152:0_153:0_154:0_155:0_156:0_157:0_158:0_159:0_160:0 | X20: 1:2_2:635_3:635_4:635_5:405_6:405_7:315_8:315_9:315_10:315_11:315_12:315_13:315_14:315_15:315_16:315_17:315_18:315_19:315_20:315_21:315_22:315_23:315_24:315_25:315_26:315_27:315_28:315_29:315_30:315_31:315_32:315_33:315_34:315_35:315_36:315_37:315_38:315_39:315_40:315_41:315_42:315_43:315_44:315_45:315_46:315_47:315_48:315_49:315_50:315_51:315_52:315_53:315_54:315_55:315_56:315_57:315_58:315_59:315_60:315_61:315_62:315_63:315_64:315_65:315_66:315_67:315_68:315_69:315_70:315_71:315_72:315_73:315_74:315_75:315_76:315_77:315_78:315_79:315_80:315_81:315_82:315_83:315_84:315_85:315_86:315_87:315_88:315_89:315_90:315_91:315_92:315_93:315_94:315_95:315_96:315_97:315_98:315_99:315_100:315_101:0_102:0_103:0_104:0_105:0_106:0_107:0_108:0_109:0_110:0_111:0_112:0_113:0_114:0_115:0_116:0_117:0_118:0_119:0_120:0_121:0_122:0_123:0_124:0_125:0_126:0_127:0_128:0_129:0_130:0_131:0_132:0_133:0_134:0_135:0_136:0_137:0_138:0_139:0_140:0_141:0_142:0_143:0_144:0_145:0_146:0_147:0_148:0_149:0_150:0_151:0_152:0_153:0_154:0_155:0_156:0_157:0_158:0_159:0_160:0 | Y20: 20010001 | Z20: 0 | AA20: 1 | AB20: 0:2500_50:5000_80:10000_125:15000_160:30000 | AC20: 10000 | AD20: 10000 | AE20: 25010001 | AF20: 40 | AG20: 0 | AH20: 0 | AI20: 0 | AJ20: 0
A21: 20302 | B21: 2 | C21: 守卫3 | D21: 喷火恶龙2 | E21: 未使用 | F21: 客户端资源组 | G21: 2 | H21: 2 | I21: 0:0 | J21: 0 | K21: 喷火恶龙 | L21: 800001021 | M21: 2 | N21: 700 | O21: 2 | P21: 14 | Q21: 0 | R21: 44 | S21: -3000 | T21: 1 | U21: 80 | V21: 1:0_2:0_3:0_4:0_5:0_6:0_7:0_8:0_9:0_10:0_11:0_12:0_13:0_14:0_15:0_16:0_17:0_18:0_19:0_20:0_21:0_22:0_23:0_24:0_25:0_26:0_27:0_28:0_29:0_30:0_31:0_32:0_33:0_34:0_35:0_36:0_37:0_38:0_39:0_40:0_41:0_42:0_43:0_44:0_45:0_46:0_47:0_48:0_49:0_50:0_51:0_52:0_53:0_54:0_55:0_56:0_57:0_58:0_59:0_60:0_61:0_62:0_63:0_64:0_65:0_66:0_67:0_68:0_69:0_70:0_71:0_72:0_73:0_74:0_75:0_76:0_77:0_78:0_79:0_80:0_81:0_82:0_83:0_84:0_85:0_86:0_87:0_88:0_89:0_90:0_91:0_92:0_93:0_94:0_95:0_96:0_97:0_98:0_99:0_100:0_101:0_102:0_103:0_104:0_105:0_106:0_107:0_108:0_109:0_110:0_111:0_112:0_113:0_114:0_115:0_116:0_117:0_118:0_119:0_120:0_121:0_122:0_123:0_124:0_125:0_126:0_127:0_128:0_129:0_130:0_131:0_132:0_133:0_134:0_135:0_136:0_137:0_138:0_139:0_140:0_141:0_142:0_143:0_144:0_145:0_146:0_147:0_148:0_149:0_150:0_151:0_152:0_153:0_154:0_155:0_156:0_157:0_158:0_159:0_160:0 | W21: 1:0_2:0_3:0_4:0_5:0_6:0_7:0_8:0_9:0_10:0_11:0_12:0_13:0_14:0_15:0_16:0_17:0_18:0_19:0_20:0_21:0_22:0_23:0_24:0_25:0_26:0_27:0_28:0_29:0_30:0_31:0_32:0_33:0_34:0_35:0_36:0_37:0_38:0_39:0_40:0_41:0_42:0_43:0_44:0_45:0_46:0_47:0_48:0_49:0_50:0_51:0_52:0_53:0_54:0_55:0_56:0_57:0_58:0_59:0_60:0_61:0_62:0_63:0_64:0_65:0_66:0_67:0_68:0_69:0_70:0_71:0_72:0_73:0_74:0_75:0_76:0_77:0_78:0_79:0_80:0_81:0_82:0_83:0_84:0_85:0_86:0_87:0_88:0_89:0_90:0_91:0_92:0_93:0_94:0_95:0_96:0_97:0_98:0_99:0_100:0_101:0_102:0_103:0_104:0_105:0_106:0_107:0_108:0_109:0_110:0_111:0_112:0_113:0_114:0_115:0_116:0_117:0_118:0_119:0_120:0_121:0_122:0_123:0_124:0_125:0_126:0_127:0_128:0_129:0_130:0_131:0_132:0_133:0_134:0_135:0_136:0_137:0_138:0_139:0_140:0_141:0_142:0_143:0_144:0_145:0_146:0_147:0_148:0_149:0_150:0_151:0_152:0_153:0_154:0_155:0_156:0_157:0_158:0_159:0_160:0 | X21: 1:2_2:635_3:635_4:635_5:405_6:405_7:315_8:315_9:315_10:315_11:315_12:315_13:315_14:315_15:315_16:315_17:315_18:315_19:315_20:315_21:315_22:315_23:315_24:315_25:315_26:315_27:315_28:315_29:315_30:315_31:315_32:315_33:315_34:315_35:315_36:315_37:315_38:315_39:315_40:315_41:315_42:315_43:315_44:315_45:315_46:315_47:315_48:315_49:315_50:315_51:315_52:315_53:315_54:315_55:315_56:315_57:315_58:315_59:315_60:315_61:315_62:315_63:315_64:315_65:315_66:315_67:315_68:315_69:315_70:315_71:315_72:315_73:315_74:315_75:315_76:315_77:315_78:315_79:315_80:315_81:315_82:315_83:315_84:315_85:315_86:315_87:315_88:315_89:315_90:315_91:315_92:315_93:315_94:315_95:315_96:315_97:315_98:315_99:315_100:315_101:0_102:0_103:0_104:0_105:0_106:0_107:0_108:0_109:0_110:0_111:0_112:0_113:0_114:0_115:0_116:0_117:0_118:0_119:0_120:0_121:0_122:0_123:0_124:0_125:0_126:0_127:0_128:0_129:0_130:0_131:0_132:0_133:0_134:0_135:0_136:0_137:0_138:0_139:0_140:0_141:0_142:0_143:0_144:0_145:0_146:0_147:0_148:0_149:0_150:0_151:0_152:0_153:0_154:0_155:0_156:0_157:0_158:0_159:0_160:0 | Y21: 20010001 | Z21: 0 | AA21: 1 | AB21: 0:2500_50:5000_80:10000_125:15000_160:30000 | AC21: 10000 | AD21: 10000 | AE21: 25010001 | AF21: 40 | AG21: 0 | AH21: 0 | AI21: 0 | AJ21: 0
A22: 20303 | B22: 2 | C22: 守卫4 | D22: 爆裂悍匪2 | E22: 未使用 | F22: 客户端资源组 | G22: 2 | H22: 2 | I22: 0:0 | J22: 0 | K22: 爆裂悍匪 | L22: 800001021 | M22: 2 | N22: 800 | O22: 2 | P22: 11 | Q22: 0 | R22: 45 | S22: -3000 | T22: 1 | U22: 100 | V22: 1:0_2:0_3:0_4:0_5:0_6:0_7:0_8:0_9:0_10:0_11:0_12:0_13:0_14:0_15:0_16:0_17:0_18:0_19:0_20:0_21:0_22:0_23:0_24:0_25:0_26:0_27:0_28:0_29:0_30:0_31:0_32:0_33:0_34:0_35:0_36:0_37:0_38:0_39:0_40:0_41:0_42:0_43:0_44:0_45:0_46:0_47:0_48:0_49:0_50:0_51:0_52:0_53:0_54:0_55:0_56:0_57:0_58:0_59:0_60:0_61:0_62:0_63:0_64:0_65:0_66:0_67:0_68:0_69:0_70:0_71:0_72:0_73:0_74:0_75:0_76:0_77:0_78:0_79:0_80:0_81:0_82:0_83:0_84:0_85:0_86:0_87:0_88:0_89:0_90:0_91:0_92:0_93:0_94:0_95:0_96:0_97:0_98:0_99:0_100:0_101:0_102:0_103:0_104:0_105:0_106:0_107:0_108:0_109:0_110:0_111:0_112:0_113:0_114:0_115:0_116:0_117:0_118:0_119:0_120:0_121:0_122:0_123:0_124:0_125:0_126:0_127:0_128:0_129:0_130:0_131:0_132:0_133:0_134:0_135:0_136:0_137:0_138:0_139:0_140:0_141:0_142:0_143:0_144:0_145:0_146:0_147:0_148:0_149:0_150:0_151:0_152:0_153:0_154:0_155:0_156:0_157:0_158:0_159:0_160:0 | W22: 1:0_2:0_3:0_4:0_5:0_6:0_7:0_8:0_9:0_10:0_11:0_12:0_13:0_14:0_15:0_16:0_17:0_18:0_19:0_20:0_21:0_22:0_23:0_24:0_25:0_26:0_27:0_28:0_29:0_30:0_31:0_32:0_33:0_34:0_35:0_36:0_37:0_38:0_39:0_40:0_41:0_42:0_43:0_44:0_45:0_46:0_47:0_48:0_49:0_50:0_51:0_52:0_53:0_54:0_55:0_56:0_57:0_58:0_59:0_60:0_61:0_62:0_63:0_64:0_65:0_66:0_67:0_68:0_69:0_70:0_71:0_72:0_73:0_74:0_75:0_76:0_77:0_78:0_79:0_80:0_81:0_82:0_83:0_84:0_85:0_86:0_87:0_88:0_89:0_90:0_91:0_92:0_93:0_94:0_95:0_96:0_97:0_98:0_99:0_100:0_101:0_102:0_103:0_104:0_105:0_106:0_107:0_108:0_109:0_110:0_111:0_112:0_113:0_114:0_115:0_116:0_117:0_118:0_119:0_120:0_121:0_122:0_123:0_124:0_125:0_126:0_127:0_128:0_129:0_130:0_131:0_132:0_133:0_134:0_135:0_136:0_137:0_138:0_139:0_140:0_141:0_142:0_143:0_144:0_145:0_146:0_147:0_148:0_149:0_150:0_151:0_152:0_153:0_154:0_155:0_156:0_157:0_158:0_159:0_160:0 | X22: 1:2_2:635_3:635_4:635_5:405_6:405_7:315_8:315_9:315_10:315_11:315_12:315_13:315_14:315_15:315_16:315_17:315_18:315_19:315_20:315_21:315_22:315_23:315_24:315_25:315_26:315_27:315_28:315_29:315_30:315_31:315_32:315_33:315_34:315_35:315_36:315_37:315_38:315_39:315_40:315_41:315_42:315_43:315_44:315_45:315_46:315_47:315_48:315_49:315_50:315_51:315_52:315_53:315_54:315_55:315_56:315_57:315_58:315_59:315_60:315_61:315_62:315_63:315_64:315_65:315_66:315_67:315_68:315_69:315_70:315_71:315_72:315_73:315_74:315_75:315_76:315_77:315_78:315_79:315_80:315_81:315_82:315_83:315_84:315_85:315_86:315_87:315_88:315_89:315_90:315_91:315_92:315_93:315_94:315_95:315_96:315_97:315_98:315_99:315_100:315_101:0_102:0_103:0_104:0_105:0_106:0_107:0_108:0_109:0_110:0_111:0_112:0_113:0_114:0_115:0_116:0_117:0_118:0_119:0_120:0_121:0_122:0_123:0_124:0_125:0_126:0_127:0_128:0_129:0_130:0_131:0_132:0_133:0_134:0_135:0_136:0_137:0_138:0_139:0_140:0_141:0_142:0_143:0_144:0_145:0_146:0_147:0_148:0_149:0_150:0_151:0_152:0_153:0_154:0_155:0_156:0_157:0_158:0_159:0_160:0 | Y22: 20010001 | Z22: 0 | AA22: 1 | AB22: 0:2500_50:5000_80:10000_125:15000_160:30000 | AC22: 10000 | AD22: 10000 | AE22: 25010001 | AF22: 40 | AG22: 0 | AH22: 0 | AI22: 0 | AJ22: 0
A23: 20304 | B23: 2 | C23: 守卫5 | D23: 斯巴达勇士2 | E23: 未使用 | F23: 客户端资源组 | G23: 2 | H23: 2 | I23: 0:0 | J23: 0 | K23: 斯巴达勇士 | L23: 800001021 | M23: 2 | N23: 1500 | O23: 2 | P23: 12 | Q23: 0 | R23: 50 | S23: -3000 | T23: 1 | U23: 100 | V23: 1:0_2:0_3:0_4:0_5:0_6:0_7:0_8:0_9:0_10:0_11:0_12:0_13:0_14:0_15:0_16:0_17:0_18:0_19:0_20:0_21:0_22:0_23:0_24:0_25:0_26:0_27:0_28:0_29:0_30:0_31:0_32:0_33:0_34:0_35:0_36:0_37:0_38:0_39:0_40:0_41:0_42:0_43:0_44:0_45:0_46:0_47:0_48:0_49:0_50:0_51:0_52:0_53:0_54:0_55:0_56:0_57:0_58:0_59:0_60:0_61:0_62:0_63:0_64:0_65:0_66:0_67:0_68:0_69:0_70:0_71:0_72:0_73:0_74:0_75:0_76:0_77:0_78:0_79:0_80:0_81:0_82:0_83:0_84:0_85:0_86:0_87:0_88:0_89:0_90:0_91:0_92:0_93:0_94:0_95:0_96:0_97:0_98:0_99:0_100:0_101:0_102:0_103:0_104:0_105:0_106:0_107:0_108:0_109:0_110:0_111:0_112:0_113:0_114:0_115:0_116:0_117:0_118:0_119:0_120:0_121:0_122:0_123:0_124:0_125:0_126:0_127:0_128:0_129:0_130:0_131:0_132:0_133:0_134:0_135:0_136:0_137:0_138:0_139:0_140:0_141:0_142:0_143:0_144:0_145:0_146:0_147:0_148:0_149:0_150:0_151:0_152:0_153:0_154:0_155:0_156:0_157:0_158:0_159:0_160:0 | W23: 1:0_2:0_3:0_4:0_5:0_6:0_7:0_8:0_9:0_10:0_11:0_12:0_13:0_14:0_15:0_16:0_17:0_18:0_19:0_20:0_21:0_22:0_23:0_24:0_25:0_26:0_27:0_28:0_29:0_30:0_31:0_32:0_33:0_34:0_35:0_36:0_37:0_38:0_39:0_40:0_41:0_42:0_43:0_44:0_45:0_46:0_47:0_48:0_49:0_50:0_51:0_52:0_53:0_54:0_55:0_56:0_57:0_58:0_59:0_60:0_61:0_62:0_63:0_64:0_65:0_66:0_67:0_68:0_69:0_70:0_71:0_72:0_73:0_74:0_75:0_76:0_77:0_78:0_79:0_80:0_81:0_82:0_83:0_84:0_85:0_86:0_87:0_88:0_89:0_90:0_91:0_92:0_93:0_94:0_95:0_96:0_97:0_98:0_99:0_100:0_101:0_102:0_103:0_104:0_105:0_106:0_107:0_108:0_109:0_110:0_111:0_112:0_113:0_114:0_115:0_116:0_117:0_118:0_119:0_120:0_121:0_122:0_123:0_124:0_125:0_126:0_127:0_128:0_129:0_130:0_131:0_132:0_133:0_134:0_135:0_136:0_137:0_138:0_139:0_140:0_141:0_142:0_143:0_144:0_145:0_146:0_147:0_148:0_149:0_150:0_151:0_152:0_153:0_154:0_155:0_156:0_157:0_158:0_159:0_160:0 | X23: 1:2_2:635_3:635_4:635_5:405_6:405_7:315_8:315_9:315_10:315_11:315_12:315_13:315_14:315_15:315_16:315_17:315_18:315_19:315_20:315_21:315_22:315_23:315_24:315_25:315_26:315_27:315_28:315_29:315_30:315_31:315_32:315_33:315_34:315_35:315_36:315_37:315_38:315_39:315_40:315_41:315_42:315_43:315_44:315_45:315_46:315_47:315_48:315_49:315_50:315_51:315_52:315_53:315_54:315_55:315_56:315_57:315_58:315_59:315_60:315_61:315_62:315_63:315_64:315_65:315_66:315_67:315_68:315_69:315_70:315_71:315_72:315_73:315_74:315_75:315_76:315_77:315_78:315_79:315_80:315_81:315_82:315_83:315_84:315_85:315_86:315_87:315_88:315_89:315_90:315_91:315_92:315_93:315_94:315_95:315_96:315_97:315_98:315_99:315_100:315_101:0_102:0_103:0_104:0_105:0_106:0_107:0_108:0_109:0_110:0_111:0_112:0_113:0_114:0_115:0_116:0_117:0_118:0_119:0_120:0_121:0_122:0_123:0_124:0_125:0_126:0_127:0_128:0_129:0_130:0_131:0_132:0_133:0_134:0_135:0_136:0_137:0_138:0_139:0_140:0_141:0_142:0_143:0_144:0_145:0_146:0_147:0_148:0_149:0_150:0_151:0_152:0_153:0_154:0_155:0_156:0_157:0_158:0_159:0_160:0 | Y23: 20010001 | Z23: 0 | AA23: 1 | AB23: 0:2500_50:5000_80:10000_125:15000_160:30000 | AC23: 10000 | AD23: 10000 | AE23: 25010001 | AF23: 40 | AG23: 0 | AH23: 0 | AI23: 0 | AJ23: 0
A24: 20305 | B24: 2 | C24: 守卫6 | D24: 毒气猛士3 | E24: 未使用 | F24: 客户端资源组 | G24: 2 | H24: 2 | I24: 0:0 | J24: 0 | K24: 变异暴徒 | L24: 800001021 | M24: 2 | N24: 3000 | O24: 2 | P24: 13 | Q24: 0 | R24: 55 | S24: -3000 | T24: 1 | U24: 100 | V24: 1:0_2:0_3:0_4:0_5:0_6:0_7:0_8:0_9:0_10:0_11:0_12:0_13:0_14:0_15:0_16:0_17:0_18:0_19:0_20:0_21:0_22:0_23:0_24:0_25:0_26:0_27:0_28:0_29:0_30:0_31:0_32:0_33:0_34:0_35:0_36:0_37:0_38:0_39:0_40:0_41:0_42:0_43:0_44:0_45:0_46:0_47:0_48:0_49:0_50:0_51:0_52:0_53:0_54:0_55:0_56:0_57:0_58:0_59:0_60:0_61:0_62:0_63:0_64:0_65:0_66:0_67:0_68:0_69:0_70:0_71:0_72:0_73:0_74:0_75:0_76:0_77:0_78:0_79:0_80:0_81:0_82:0_83:0_84:0_85:0_86:0_87:0_88:0_89:0_90:0_91:0_92:0_93:0_94:0_95:0_96:0_97:0_98:0_99:0_100:0_101:0_102:0_103:0_104:0_105:0_106:0_107:0_108:0_109:0_110:0_111:0_112:0_113:0_114:0_115:0_116:0_117:0_118:0_119:0_120:0_121:0_122:0_123:0_124:0_125:0_126:0_127:0_128:0_129:0_130:0_131:0_132:0_133:0_134:0_135:0_136:0_137:0_138:0_139:0_140:0_141:0_142:0_143:0_144:0_145:0_146:0_147:0_148:0_149:0_150:0_151:0_152:0_153:0_154:0_155:0_156:0_157:0_158:0_159:0_160:0 | W24: 1:0_2:0_3:0_4:0_5:0_6:0_7:0_8:0_9:0_10:0_11:0_12:0_13:0_14:0_15:0_16:0_17:0_18:0_19:0_20:0_21:0_22:0_23:0_24:0_25:0_26:0_27:0_28:0_29:0_30:0_31:0_32:0_33:0_34:0_35:0_36:0_37:0_38:0_39:0_40:0_41:0_42:0_43:0_44:0_45:0_46:0_47:0_48:0_49:0_50:0_51:0_52:0_53:0_54:0_55:0_56:0_57:0_58:0_59:0_60:0_61:0_62:0_63:0_64:0_65:0_66:0_67:0_68:0_69:0_70:0_71:0_72:0_73:0_74:0_75:0_76:0_77:0_78:0_79:0_80:0_81:0_82:0_83:0_84:0_85:0_86:0_87:0_88:0_89:0_90:0_91:0_92:0_93:0_94:0_95:0_96:0_97:0_98:0_99:0_100:0_101:0_102:0_103:0_104:0_105:0_106:0_107:0_108:0_109:0_110:0_111:0_112:0_113:0_114:0_115:0_116:0_117:0_118:0_119:0_120:0_121:0_122:0_123:0_124:0_125:0_126:0_127:0_128:0_129:0_130:0_131:0_132:0_133:0_134:0_135:0_136:0_137:0_138:0_139:0_140:0_141:0_142:0_143:0_144:0_145:0_146:0_147:0_148:0_149:0_150:0_151:0_152:0_153:0_154:0_155:0_156:0_157:0_158:0_159:0_160:0 | X24: 1:2_2:635_3:635_4:635_5:405_6:405_7:315_8:315_9:315_10:315_11:315_12:315_13:315_14:315_15:315_16:315_17:315_18:315_19:315_20:315_21:315_22:315_23:315_24:315_25:315_26:315_27:315_28:315_29:315_30:315_31:315_32:315_33:315_34:315_35:315_36:315_37:315_38:315_39:315_40:315_41:315_42:315_43:315_44:315_45:315_46:315_47:315_48:315_49:315_50:315_51:315_52:315_53:315_54:315_55:315_56:315_57:315_58:315_59:315_60:315_61:315_62:315_63:315_64:315_65:315_66:315_67:315_68:315_69:315_70:315_71:315_72:315_73:315_74:315_75:315_76:315_77:315_78:315_79:315_80:315_81:315_82:315_83:315_84:315_85:315_86:315_87:315_88:315_89:315_90:315_91:315_92:315_93:315_94:315_95:315_96:315_97:315_98:315_99:315_100:315_101:0_102:0_103:0_104:0_105:0_106:0_107:0_108:0_109:0_110:0_111:0_112:0_113:0_114:0_115:0_116:0_117:0_118:0_119:0_120:0_121:0_122:0_123:0_124:0_125:0_126:0_127:0_128:0_129:0_130:0_131:0_132:0_133:0_134:0_135:0_136:0_137:0_138:0_139:0_140:0_141:0_142:0_143:0_144:0_145:0_146:0_147:0_148:0_149:0_150:0_151:0_152:0_153:0_154:0_155:0_156:0_157:0_158:0_159:0_160:0 | Y24: 20010001 | Z24: 0 | AA24: 1 | AB24: 0:2500_50:5000_80:10000_125:15000_160:30000 | AC24: 10000 | AD24: 10000 | AE24: 25010001 | AF24: 40 | AG24: 0 | AH24: 0 | AI24: 0 | AJ24: 0
